Workbook

Sheet Energy Schedule
C1: 44896 | F1: =C1+1 -> 44897 | I1: =F1+1 -> 44898 | L1: =I1+1 -> 44899 | O1: =L1+1 -> 44900 | R1: =O1+1 -> 44901 | U1: =R1+1 -> 44902 | X1: =U1+1 -> 44903 | AA1: =X1+1 -> 44904 | AD1: =AA1+1 -> 44905 | AG1: =AD1+1 -> 44906 | AJ1: =AG1+1 -> 44907 | AM1: =AJ1+1 -> 44908 | AP1: =AM1+1 -> 44909 | AS1: =AP1+1 -> 44910 | AV1: =AS1+1 -> 44911 | AY1: =AV1+1 -> 44912 | BB1: =AY1+1 -> 44913 | BE1: =BB1+1 -> 44914 | BH1: =BE1+1 -> 44915 | BK1: =BH1+1 -> 44916 | BN1: =BK1+1 -> 44917 | BQ1: =BN1+1 -> 44918 | BT1: =BQ1+1 -> 44919 | BW1: =BT1+1 -> 44920 | BZ1: =BW1+1 -> 44921 | CC1: =BZ1+1 -> 44922 | CF1: =CC1+1 -> 44923 | CI1: =CF1+1 -> 44924 | CL1: =CI1+1 -> 44925 | CO1: =CL1+1 -> 44926
C2: GDAM | D2: DAM | E2: RTM | F2: GDAM | G2: DAM | H2: RTM | I2: GDAM | J2: DAM | K2: RTM | L2: GDAM | M2: DAM | N2: RTM | O2: GDAM | P2: DAM | Q2: RTM | R2: GDAM | S2: DAM | T2: RTM | U2: GDAM | V2: DAM | W2: RTM | X2: GDAM | Y2: DAM | Z2: RTM | AA2: GDAM | AB2: DAM | AC2: RTM | AD2: GDAM | AE2: DAM | AF2: RTM | AG2: GDAM | AH2: DAM | AI2: RTM | AJ2: GDAM | AK2: DAM | AL2: RTM | AM2: GDAM | AN2: DAM | AO2: RTM | AP2: GDAM | AQ2: DAM | AR2: RTM | AS2: GDAM | AT2: DAM | AU2: RTM | AV2: GDAM | AW2: DAM | AX2: RTM | AY2: GDAM | AZ2: DAM | BA2: RTM | BB2: GDAM | BC2: DAM | BD2: RTM | BE2: GDAM | BF2: DAM | BG2: RTM | BH2: GDAM | BI2: DAM | BJ2: RTM | BK2: GDAM | BL2: DAM | BM2: RTM | BN2: GDAM | BO2: DAM | BP2: RTM | BQ2: GDAM | BR2: DAM | BS2: RTM | BT2: GDAM | BU2: DAM | BV2: RTM | BW2: GDAM | BX2: DAM | BY2: RTM | BZ2: GDAM | CA2: DAM | CB2: RTM | CC2: GDAM | CD2: DAM | CE2: RTM | CF2: GDAM | CG2: DAM | CH2: RTM | CI2: GDAM | CJ2: DAM | CK2: RTM | CL2: GDAM | CM2: DAM | CN2: RTM | CO2: GDAM | CP2: DAM | CQ2: RTM
A3: CTU Losses | D3: 0.0343 | G3: 0.0343 | J3: 0.0343 | M3: 0.0343 | P3: 0.0361 | R3: 0.0361 | S3: 0.0361 | V3: 0.0361 | W3: 0.0361 | Y3: 0.0361 | Z3: 0.0361 | AB3: 0.0361 | AE3: 0.0361 | AH3: 0.0361 | AK3: 0.0382 | AN3: 0.0382 | AQ3: 0.0382 | AT3: 0.0382 | AW3: 0.0382 | AZ3: 0.0382 | BC3: 0.0382 | BF3: 0.0418 | BI3: 0.0418 | BL3: 0.0418 | BO3: 0.0418 | BR3: 0.0418 | BU3: 0.0418 | BX3: 0.0418 | CA3: 0.0419 | CD3: 0.0419 | CG3: 0.0419 | CJ3: 0.0419 | CM3: 0.0419
A4: CTU Charges | D4: 457.6 | G4: 457.6 | J4: 457.6 | M4: 457.6 | P4: 457.6 | S4: 457.6 | V4: 457.6 | Y4: 457.6 | AB4: 457.6 | AE4: 457.6 | AH4: 457.6 | AK4: 457.6 | AN4: 457.6 | AQ4: 457.6 | AT4: 457.6 | AW4: 457.6 | BO4: 457.6 | BR4: 457.6 | BU4: 457.6 | BX4: 457.6 | CA4: 457.6 | CD4: 484.8 | CG4: 484.8 | CJ4: 484.8 | CM4: 484.8
A5: Cost | D5: 45070.355 | E5: 3103.11 | G5: 46896.22 | J5: 38325.914 | K5: 14307.76 | M5: 83092.96 | N5: 12749.83 | P5: 39837.968 | Q5: 16147.49 | S5: 54907.277 | T5: 13002.64 | V5: 33736.898 | W5: 22760.98 | Y5: 51549.744 | Z5: 32714.22 | AB5: 55906.487 | AC5: 28235.38 | AE5: 70274.661 | AH5: 98538.321 | AI5: 27909.59 | AK5: 63830.988 | AL5: 24341.29 | AN5: 64149.079 | AO5: 8811.53 | AQ5: 43154.523 | AR5: 24088.83 | AT5: 49631.555 | AU5: 12125.1 | AW5: 28682.671 | AX5: 4361.8 | AZ5: 29034.378 | BA5: 11232.94 | BC5: 44876.773 | BD5: 36010.11 | BF5: 23821.927 | BG5: 18669.45 | BI5: 24262.558 | BJ5: 8641.65 | BL5: 27772.575 | BM5: 35135.35 | BO5: 28861.726 | BP5: 19716.8 | BR5: 26822.584 | BS5: 15252.89 | BU5: 49873.604 | BV5: 8203.36 | BX5: 48944.949 | CA5: 23502.102 | CD5: 26051.972 | CG5: 31764.668 | CJ5: 21325.134 | CM5: 30980.829
A6: NLDC App Fee | D6: 9.09 | E6: 13.7 | G6: 8.91 | J6: 8.99 | K6: 13.19 | M6: 7.67 | N6: 14.29 | P6: 8.18 | Q6: 13.55 | S6: 8.35 | T6: 12.53 | V6: 8.61 | W6: 12.89 | Y6: 8.61 | Z6: 12.53 | AB6: 8.28 | AC6: 12.32 | AE6: 7.91 | AH6: 7.36 | AI6: 12.92 | AK6: 7.44 | AL6: 11.74 | AN6: 7.69 | AO6: 12.56 | AQ6: 7.62 | AR6: 12.92 | AT6: 8.04 | AU6: 15.43 | AW6: 8.59 | AX6: 24.39 | AZ6: 8.5 | BA6: 18.66 | BC6: 8.42 | BD6: 14.16 | BF6: 8.25 | BG6: 13.66 | BI6: 8.22 | BJ6: 12.92 | BL6: 7.74 | BM6: 13.16 | BO6: 8.13 | BP6: 12.53 | BR6: 7.69 | BS6: 11.79 | BU6: 7.42 | BV6: 13.02 | BX6: 7.22 | CA6: 7.65 | CD6: 7.41 | CG6: 7.36 | CJ6: 7.58 | CM6: 8.16
A7: 00:00 - 00:15 | B7: C5 | D7: 1 | E7: 0 | G7: 1 | J7: 0 | K7: 0 | M7: 0.5 | N7: 0 | P7: 0.5 | Q7: 0 | S7: 0.5 | T7: 0 | V7: 0.5 | W7: 0 | Y7: 0.5 | Z7: 0 | AB7: 0.5 | AC7: 0 | AE7: 0.5 | AH7: 0.5 | AI7: 0 | AK7: 0.5 | AL7: 0 | AN7: 0.5 | AO7: 0 | AQ7: 0.3 | AR7: 0.3 | AT7: 0.3 | AU7: 0 | AW7: 0.3 | AX7: 0 | AZ7: 0.3 | BA7: 0 | BC7: 0.3 | BD7: 0 | BF7: 0.3 | BG7: 0 | BI7: 0.3 | BJ7: 0 | BL7: 0.3 | BM7: 0.3 | BO7: 0.3 | BP7: 0.3 | BR7: 0.3 | BS7: 0.3 | BU7: 0.3 | BV7: 0.3 | BX7: 0.3 | CA7: 0.3 | CD7: 0.3 | CG7: 0.3 | CJ7: 0.3 | CM7: 0.3
A8: 00:15 - 00:30 | D8: 1 | E8: 0 | G8: 1 | J8: 0.5 | K8: 0 | M8: 0.5 | N8: 0 | P8: 0.5 | Q8: 0 | S8: 0.5 | T8: 0 | V8: 0.5 | W8: 0 | Y8: 0.5 | Z8: 0 | AB8: 0.5 | AC8: 0 | AE8: 0.5 | AH8: 0.5 | AI8: 0 | AK8: 0.5 | AL8: 0 | AN8: 0.5 | AO8: 0 | AQ8: 0.3 | AR8: 0.3 | AT8: 0.3 | AU8: 0 | AW8: 0.3 | AX8: 0 | AZ8: 0.3 | BA8: 0.3 | BC8: 0.3 | BD8: 0 | BF8: 0.3 | BG8: 0 | BI8: 0.3 | BJ8: 0 | BL8: 0.3 | BM8: 0.3 | BO8: 0.3 | BP8: 0.3 | BR8: 0.3 | BS8: 0.3 | BU8: 0.3 | BV8: 0.3 | BX8: 0.3 | CA8: 0.3 | CD8: 0.3 | CG8: 0.3 | CJ8: 0.3 | CM8: 0.3
A9: 00:30 - 00:45 | D9: 1 | E9: 0 | G9: 1 | J9: 0.5 | K9: 0 | M9: 0.5 | N9: 0 | P9: 0.5 | Q9: 0 | S9: 0.5 | T9: 0 | V9: 0.5 | W9: 0 | Y9: 0.5 | Z9: 0 | AB9: 0.5 | AC9: 0 | AE9: 0.5 | AH9: 0.5 | AI9: 0 | AK9: 0.5 | AL9: 0 | AN9: 0.5 | AO9: 0 | AQ9: 0.3 | AR9: 0.3 | AT9: 0.3 | AU9: 0 | AW9: 0.3 | AX9: 0 | AZ9: 0.3 | BA9: 0.3 | BC9: 0.3 | BD9: 0 | BF9: 0.3 | BG9: 0 | BI9: 0.3 | BJ9: 0 | BL9: 0.3 | BM9: 0 | BO9: 0.3 | BP9: 0 | BR9: 0.3 | BS9: 0.3 | BU9: 0.3 | BV9: 0.3 | BX9: 0.3 | CA9: 0.3 | CD9: 0.3 | CG9: 0.3 | CJ9: 0.3 | CM9: 0.3
A10: 00:45 - 01:00 | D10: 1 | E10: 0 | G10: 1 | J10: 0.5 | K10: 0 | M10: 0.5 | N10: 0 | P10: 0.5 | Q10: 0 | S10: 0.5 | T10: 0 | V10: 0.5 | W10: 0 | Y10: 0.5 | Z10: 0 | AB10: 0.5 | AC10: 0 | AE10: 0.5 | AH10: 0.5 | AI10: 0 | AK10: 0.5 | AL10: 0 | AN10: 0.5 | AO10: 0 | AQ10: 0.3 | AR10: 0.3 | AT10: 0.3 | AU10: 0 | AW10: 0.3 | AX10: 0.3 | AZ10: 0.3 | BA10: 0.3 | BC10: 0.3 | BD10: 0 | BF10: 0.3 | BG10: 0 | BI10: 0.3 | BJ10: 0 | BL10: 0.3 | BM10: 0 | BO10: 0.3 | BP10: 0 | BR10: 0.3 | BS10: 0.3 | BU10: 0.3 | BV10: 0.3 | BX10: 0.3 | CA10: 0.3 | CD10: 0.3 | CG10: 0.3 | CJ10: 0.3 | CM10: 0.3
A11: 01:00 - 01:15 | D11: 1 | E11: 0 | G11: 1 | J11: 0.5 | K11: 0 | M11: 0.5 | N11: 0 | P11: 0.5 | Q11: 0 | S11: 0.5 | T11: 0 | V11: 0.5 | W11: 0 | Y11: 0.5 | Z11: 0 | AB11: 0.5 | AC11: 0 | AE11: 0.5 | AH11: 0.5 | AI11: 0 | AK11: 0.5 | AL11: 0 | AN11: 0.5 | AO11: 0 | AQ11: 0.3 | AR11: 0.3 | AT11: 0.3 | AU11: 0.2 | AW11: 0.3 | AX11: 0.3 | AZ11: 0.3 | BA11: 0 | BC11: 0.3 | BD11: 0.3 | BF11: 0.3 | BG11: 0 | BI11: 0.3 | BJ11: 0 | BL11: 0.3 | BM11: 0.3 | BO11: 0.3 | BP11: 0.3 | BR11: 0.3 | BS11: 0.3 | BU11: 0.3 | BV11: 0.3 | BX11: 0.3 | CA11: 0.3 | CD11: 0.3 | CG11: 0.3 | CJ11: 0.3 | CM11: 0.3
A12: 01:15 - 01:30 | D12: 1 | E12: 0 | G12: 1 | J12: 0.5 | K12: 0 | M12: 0.5 | N12: 0 | P12: 0.5 | Q12: 0 | S12: 0.5 | T12: 0 | V12: 0.5 | W12: 0 | Y12: 0.5 | Z12: 0 | AB12: 0.5 | AC12: 0 | AE12: 0.5 | AH12: 0.5 | AI12: 0 | AK12: 0.5 | AL12: 0 | AN12: 0.5 | AO12: 0 | AQ12: 0.3 | AR12: 0.3 | AT12: 0.3 | AU12: 0.2 | AW12: 0.3 | AX12: 0.3 | AZ12: 0.3 | BA12: 0 | BC12: 0.3 | BD12: 0.3 | BF12: 0.3 | BG12: 0 | BI12: 0.3 | BJ12: 0 | BL12: 0.3 | BM12: 0.3 | BO12: 0.3 | BP12: 0.3 | BR12: 0.3 | BS12: 0.3 | BU12: 0.3 | BV12: 0.3 | BX12: 0.3 | CA12: 0.3 | CD12: 0.3 | CG12: 0.3 | CJ12: 0.3 | CM12: 0.3
A13: 01:30 - 01:45 | D13: 1 | E13: 0 | G13: 1 | J13: 0.5 | K13: 0 | M13: 0.5 | N13: 0 | P13: 0.5 | Q13: 0 | S13: 0.5 | T13: 0 | V13: 0.5 | W13: 0 | Y13: 0.5 | Z13: 0 | AB13: 0.5 | AC13: 0 | AE13: 0.5 | AH13: 0.5 | AI13: 0 | AK13: 0.5 | AL13: 0 | AN13: 0.5 | AO13: 0 | AQ13: 0.3 | AR13: 0.3 | AT13: 0.3 | AU13: 0.2 | AW13: 0.3 | AX13: 0 | AZ13: 0.3 | BA13: 0 | BC13: 0.3 | BD13: 0.3 | BF13: 0.3 | BG13: 0 | BI13: 0.3 | BJ13: 0 | BL13: 0.3 | BM13: 0.3 | BO13: 0.3 | BP13: 0.3 | BR13: 0.3 | BS13: 0.3 | BU13: 0.3 | BV13: 0.3 | BX13: 0.3 | CA13: 0.3 | CD13: 0.3 | CG13: 0.3 | CJ13: 0.3 | CM13: 0.3
A14: 01:45 - 02:00 | D14: 1 | E14: 0 | G14: 1 | J14: 0.5 | K14: 0 | M14: 0.5 | N14: 0 | P14: 0.5 | Q14: 0 | S14: 0.5 | T14: 0 | V14: 0.5 | W14: 0 | Y14: 0.5 | Z14: 0 | AB14: 0.5 | AC14: 0 | AE14: 0.5 | AH14: 0.5 | AI14: 0 | AK14: 0.5 | AL14: 0 | AN14: 0.5 | AO14: 0 | AQ14: 0.3 | AR14: 0.3 | AT14: 0.3 | AU14: 0.2 | AW14: 0.3 | AX14: 0 | AZ14: 0.3 | BA14: 0 | BC14: 0.3 | BD14: 0.3 | BF14: 0.3 | BG14: 0 | BI14: 0.3 | BJ14: 0 | BL14: 0.3 | BM14: 0.3 | BO14: 0.3 | BP14: 0.3 | BR14: 0.3 | BS14: 0.3 | BU14: 0.3 | BV14: 0.3 | BX14: 0.3 | CA14: 0.3 | CD14: 0.3 | CG14: 0.3 | CJ14: 0.3 | CM14: 0.3
A15: 02:00 - 02:15 | D15: 1 | E15: 0 | G15: 1 | J15: 0.5 | K15: 0 | M15: 0.5 | N15: 0 | P15: 0.5 | Q15: 0 | S15: 0.5 | T15: 0 | V15: 0.5 | W15: 0 | Y15: 0.5 | Z15: 0 | AB15: 0.5 | AC15: 0 | AE15: 0.5 | AH15: 0.5 | AI15: 0 | AK15: 0.5 | AL15: 0 | AN15: 0.5 | AO15: 0 | AQ15: 0.3 | AR15: 0.3 | AT15: 0.3 | AU15: 0.2 | AW15: 0.3 | AX15: 0 | AZ15: 0.3 | BA15: 0 | BC15: 0.3 | BD15: 0.3 | BF15: 0.3 | BG15: 0 | BI15: 0.3 | BJ15: 0.3 | BL15: 0.3 | BM15: 0.3 | BO15: 0.3 | BP15: 0.3 | BR15: 0.3 | BS15: 0.3 | BU15: 0.3 | BV15: 0.3 | BX15: 0.3 | CA15: 0.3 | CD15: 0.3 | CG15: 0.3 | CJ15: 0.3 | CM15: 0.3
A16: 02:15 - 02:30 | D16: 1 | E16: 0 | G16: 1 | J16: 0.5 | K16: 0 | M16: 0.5 | N16: 0 | P16: 0.5 | Q16: 0 | S16: 0.5 | T16: 0 | V16: 0.5 | W16: 0 | Y16: 0.5 | Z16: 0 | AB16: 0.5 | AC16: 0 | AE16: 0.5 | AH16: 0.5 | AI16: 0 | AK16: 0.5 | AL16: 0 | AN16: 0.5 | AO16: 0 | AQ16: 0.3 | AR16: 0.3 | AT16: 0.3 | AU16: 0.2 | AW16: 0.3 | AX16: 0 | AZ16: 0.3 | BA16: 0 | BC16: 0.3 | BD16: 0 | BF16: 0.3 | BG16: 0 | BI16: 0.3 | BJ16: 0.3 | BL16: 0.3 | BM16: 0.3 | BO16: 0.3 | BP16: 0.3 | BR16: 0.3 | BS16: 0.3 | BU16: 0.3 | BV16: 0.3 | BX16: 0.3 | CA16: 0.3 | CD16: 0.3 | CG16: 0.3 | CJ16: 0.3 | CM16: 0.3
A17: 02:30 - 02:45 | D17: 1 | E17: 0 | G17: 1 | J17: 0.5 | K17: 0 | M17: 0.5 | N17: 0 | P17: 0.5 | Q17: 0 | S17: 0.5 | T17: 0 | V17: 0.5 | W17: 0 | Y17: 0.5 | Z17: 0 | AB17: 0.5 | AC17: 0 | AE17: 0.5 | AH17: 0.5 | AI17: 0 | AK17: 0.5 | AL17: 0 | AN17: 0.5 | AO17: 0 | AQ17: 0.3 | AR17: 0.3 | AT17: 0.3 | AU17: 0.2 | AW17: 0.3 | AX17: 0 | AZ17: 0.3 | BA17: 0.3 | BC17: 0.3 | BD17: 0 | BF17: 0.3 | BG17: 0 | BI17: 0.3 | BJ17: 0.3 | BL17: 0.3 | BM17: 0.3 | BO17: 0.3 | BP17: 0.3 | BR17: 0.3 | BS17: 0.3 | BU17: 0.3 | BV17: 0.3 | BX17: 0.3 | CA17: 0.3 | CD17: 0.3 | CG17: 0.3 | CJ17: 0.3 | CM17: 0.3
A18: 02:45 - 03:00 | D18: 1 | E18: 0 | G18: 1 | J18: 0.5 | K18: 0 | M18: 0.5 | N18: 0 | P18: 0.5 | Q18: 0 | S18: 0.5 | T18: 0 | V18: 0.5 | W18: 0 | Y18: 0.5 | Z18: 0 | AB18: 0.5 | AC18: 0 | AE18: 0.5 | AH18: 0.5 | AI18: 0 | AK18: 0.5 | AL18: 0 | AN18: 0.5 | AO18: 0 | AQ18: 0.3 | AR18: 0.3 | AT18: 0.3 | AU18: 0.2 | AW18: 0.3 | AX18: 0.3 | AZ18: 0.3 | BA18: 0.3 | BC18: 0.3 | BD18: 0 | BF18: 0.3 | BG18: 0 | BI18: 0.3 | BJ18: 0.3 | BL18: 0.3 | BM18: 0.3 | BO18: 0.3 | BP18: 0.3 | BR18: 0.3 | BS18: 0.3 | BU18: 0.3 | BV18: 0.3 | BX18: 0.3 | CA18: 0.3 | CD18: 0.3 | CG18: 0.3 | CJ18: 0.3 | CM18: 0.3
A19: 03:00 - 03:15 | D19: 1 | E19: 0 | G19: 1 | J19: 0.5 | K19: 0 | M19: 0.5 | N19: 0 | P19: 0.5 | Q19: 0 | S19: 0.5 | T19: 0 | V19: 0.5 | W19: 0 | Y19: 0.5 | Z19: 0 | AB19: 0.5 | AC19: 0 | AE19: 0.5 | AH19: 0.5 | AI19: 0 | AK19: 0.5 | AL19: 0 | AN19: 0.5 | AO19: 0 | AQ19: 0.3 | AR19: 0.3 | AT19: 0.3 | AU19: 0.2 | AW19: 0.3 | AX19: 0 | AZ19: 0.3 | BA19: 0.3 | BC19: 0.3 | BD19: 0.3 | BF19: 0.3 | BG19: 0 | BI19: 0.3 | BJ19: 0.3 | BL19: 0.3 | BM19: 0.3 | BO19: 0.3 | BP19: 0.3 | BR19: 0.3 | BS19: 0.3 | BU19: 0.3 | BV19: 0.3 | BX19: 0.3 | CA19: 0.3 | CD19: 0.3 | CG19: 0.3 | CJ19: 0.3 | CM19: 0.3
... A26: 04:45 - 05:00 | D26: 1 | E26: 0 | G26: 1 | J26: 0.5 | K26: 0 | M26: 0.5 | N26: 0 | P26: 0.5 | Q26: 0 | S26: 0.5 | T26: 0 | V26: 0.5 | W26: 0 | Y26: 0.5 | Z26: 0 | AB26: 0.5 | AC26: 0 | AE26: 0.5 | AH26: 0.5 | AI26: 0 | AK26: 0.5 | AL26: 0 | AN26: 0.5 | AO26: 0 | AQ26: 0.3 | AR26: 0 | AT26: 0.3 | AU26: 0 | AW26: 0.3 | AX26: 0 | AZ26: 0.3 | BA26: 0 | BC26: 0.3 | BD26: 0 | BF26: 0.3 | BG26: 0 | BI26: 0.3 | BJ26: 0 | BL26: 0.3 | BM26: 0.3 | BO26: 0.3 | BP26: 0.3 | BR26: 0.3 | BS26: 0 | BU26: 0.3 | BV26: 0 | BX26: 0.3 | CA26: 0.3 | CD26: 0.3 | CG26: 0.3 | CJ26: 0.3 | CM26: 0.3
A27: 05:00 - 05:15 | B27: C4 | D27: 1 | E27: 0 | G27: 1 | J27: 0.5 | K27: 0 | M27: 0.5 | N27: 0 | P27: 0.5 | Q27: 0 | S27: 0.5 | T27: 0 | V27: 0.5 | W27: 0 | Y27: 0.5 | Z27: 0 | AB27: 0.5 | AC27: 0 | AE27: 0.5 | AH27: 0.5 | AI27: 0 | AK27: 0.5 | AL27: 0 | AN27: 0.5 | AO27: 0 | AQ27: 0.5 | AR27: 0.5 | AT27: 0.5 | AU27: 0.3 | AW27: 0.5 | AX27: 0 | AZ27: 0.5 | BA27: 0 | BC27: 0.5 | BD27: 0.5 | BF27: 0.5 | BG27: 0 | BI27: 0.5 | BJ27: 0 | BL27: 0.5 | BM27: 0.2 | BO27: 0.5 | BP27: 0.2 | BR27: 0.5 | BS27: 0 | BU27: 0.5 | BV27: 0 | BX27: 0.5 | CA27: 0.5 | CD27: 0.5 | CG27: 0.5 | CJ27: 0.5 | CM27: 0.5
A28: 05:15 - 05:30 | D28: 1 | E28: 0 | G28: 1 | J28: 0.5 | K28: 0 | M28: 0.5 | N28: 0 | P28: 0.5 | Q28: 0 | S28: 0.5 | T28: 0 | V28: 0.5 | W28: 0 | Y28: 0.5 | Z28: 0 | AB28: 0.5 | AC28: 0 | AE28: 0.5 | AH28: 0.5 | AI28: 0 | AK28: 0.5 | AL28: 0 | AN28: 0.5 | AO28: 0 | AQ28: 0.5 | AR28: 0 | AT28: 0.5 | AU28: 0.3 | AW28: 0.5 | AX28: 0 | AZ28: 0.5 | BA28: 0.6 | BC28: 0.5 | BD28: 0 | BF28: 0.5 | BG28: 0 | BI28: 0.5 | BJ28: 0 | BL28: 0.5 | BM28: 0.2 | BO28: 0.5 | BP28: 0.2 | BR28: 0.5 | BS28: 0 | BU28: 0.5 | BV28: 0.3 | BX28: 0.5 | CA28: 0.5 | CD28: 0.5 | CG28: 0.5 | CJ28: 0.5 | CM28: 0.5
A29: 05:30 - 05:45 | D29: 1 | E29: 0 | G29: 1 | J29: 0 | K29: 0 | M29: 0.5 | N29: 0 | P29: 0.5 | Q29: 0 | S29: 0.5 | T29: 0 | V29: 0.5 | W29: 0 | Y29: 0.5 | Z29: 0 | AB29: 0.5 | AC29: 0 | AE29: 0.5 | AH29: 0.5 | AI29: 0 | AK29: 0.5 | AL29: 0 | AN29: 0.5 | AO29: 0 | AQ29: 0.5 | AR29: 0 | AT29: 0.5 | AU29: 0 | AW29: 0.5 | AX29: 0 | AZ29: 0 | BA29: 0.6 | BC29: 0 | BD29: 0 | BF29: 0 | BG29: 0 | BI29: 0 | BJ29: 0.5 | BL29: 0.5 | BM29: 0.2 | BO29: 0.5 | BP29: 0.2 | BR29: 0.5 | BS29: 0.4 | BU29: 0.5 | BV29: 0 | BX29: 0.5 | CA29: 0.5 | CD29: 0.5 | CG29: 0.5 | CJ29: 0.5 | CM29: 0.5
A30: 05:45 - 06:00 | D30: 0 | E30: 0 | G30: 1 | J30: 0 | K30: 0 | M30: 0.5 | N30: 0 | P30: 0.5 | Q30: 0 | S30: 0.5 | T30: 0 | V30: 0 | W30: 0 | Y30: 0 | Z30: 0 | AB30: 0 | AC30: 0 | AE30: 0.5 | AH30: 0.5 | AI30: 0 | AK30: 0.5 | AL30: 0 | AN30: 0.5 | AO30: 0 | AQ30: 0.5 | AR30: 0 | AT30: 0.5 | AU30: 0 | AW30: 0 | AX30: 0 | AZ30: 0 | BA30: 0 | BC30: 0 | BD30: 0.5 | BF30: 0 | BG30: 0 | BI30: 0 | BJ30: 0.5 | BL30: 0.5 | BM30: 0.2 | BO30: 0.5 | BP30: 0.2 | BR30: 0.5 | BS30: 0.4 | BU30: 0.5 | BV30: 0.3 | BX30: 0.5 | CA30: 0.5 | CD30: 0.5 | CG30: 0.5 | CJ30: 0 | CM30: 0
A31: 06:00 - 06:15 | B31: C1 | D31: 0 | E31: 0 | G31: 0 | J31: 0 | K31: 0.5 | M31: 0.5 | N31: 0 | P31: 0.5 | Q31: 0 | S31: 0.5 | T31: 0 | V31: 0 | W31: 0 | Y31: 0 | Z31: 0 | AB31: 0 | AC31: 0 | AE31: 0.5 | AH31: 0.5 | AI31: 0 | AK31: 0.5 | AL31: 0 | AN31: 0.5 | AO31: 0 | AQ31: 0.5 | AR31: 0.5 | AT31: 0.5 | AU31: 0 | AW31: 0 | AX31: 0 | AZ31: 0 | BA31: 0 | BC31: 0 | BD31: 0.6 | BF31: 0.5 | BG31: 0 | BI31: 0.5 | BJ31: 0 | BL31: 0.5 | BM31: 0.2 | BO31: 0.5 | BP31: 0.2 | BR31: 0.5 | BS31: 0.1 | BU31: 0.5 | BV31: 0.1 | BX31: 0.5 | CA31: 0.5 | CD31: 0.5 | CG31: 0.5 | CJ31: 0.5 | CM31: 0.5
A32: 06:15 - 06:30 | D32: 0 | E32: 0 | G32: 0 | J32: 0 | K32: 0.5 | M32: 0.5 | N32: 0 | P32: 0.5 | Q32: 0 | S32: 0 | T32: 0 | V32: 0 | W32: 0 | Y32: 0 | Z32: 0 | AB32: 0 | AC32: 0 | AE32: 0.5 | AH32: 0.5 | AI32: 0 | AK32: 0.5 | AL32: 0 | AN32: 0.5 | AO32: 0 | AQ32: 0 | AR32: 0.5 | AT32: 0 | AU32: 0 | AW32: 0 | AX32: 0 | AZ32: 0 | BA32: 0 | BC32: 0 | BD32: 0.6 | BF32: 0 | BG32: 0.6 | BI32: 0.5 | BJ32: 0 | BL32: 0 | BM32: 0.7 | BO32: 0.5 | BP32: 0.7 | BR32: 0.5 | BS32: 0.1 | BU32: 0 | BV32: 0.5 | BX32: 0.5 | CA32: 0.5 | CD32: 0.5 | CG32: 0.5 | CJ32: 0 | CM32: 0
A33: 06:30 - 06:45 | D33: 0 | E33: 0 | G33: 0 | J33: 0 | K33: 0 | M33: 0.5 | N33: 0 | P33: 0.5 | Q33: 0 | S33: 0 | T33: 0 | V33: 0 | W33: 0 | Y33: 0 | Z33: 0 | AB33: 0 | AC33: 0 | AE33: 0 | AH33: 0.5 | AI33: 0 | AK33: 0 | AL33: 0.6 | AN33: 0 | AO33: 0.6 | AQ33: 0.5 | AR33: 0.5 | AT33: 0 | AU33: 0 | AW33: 0 | AX33: 0 | AZ33: 0 | BA33: 0 | BC33: 0 | BD33: 0.6 | BF33: 0 | BG33: 0.6 | BI33: 0 | BJ33: 0.6 | BL33: 0 | BM33: 0.7 | BO33: 0 | BP33: 0.7 | BR33: 0 | BS33: 0.6 | BU33: 0 | BV33: 0 | BX33: 0.5 | CA33: 0 | CD33: 0.5 | CG33: 0.5 | CJ33: 0 | CM33: 0
A34: 06:45 - 07:00 | D34: 0 | E34: 0 | G34: 0 | J34: 0 | K34: 0 | M34: 0 | N34: 0 | P34: 0 | Q34: 0 | S34: 0 | T34: 0 | V34: 0 | W34: 0 | Y34: 0 | Z34: 0 | AB34: 0 | AC34: 0 | AE34: 0 | AH34: 0.5 | AI34: 0 | AK34: 0 | AL34: 0 | AN34: 0 | AO34: 0.6 | AQ34: 0 | AR34: 0 | AT34: 0 | AU34: 0 | AW34: 0 | AX34: 0 | AZ34: 0 | BA34: 0 | BC34: 0 | BD34: 0 | BF34: 0 | BG34: 0 | BI34: 0 | BJ34: 0.6 | BL34: 0 | BM34: 0 | BO34: 0 | BP34: 0 | BR34: 0 | BS34: 0 | BU34: 0 | BV34: 0 | BX34: 0 | CA34: 0 | CD34: 0 | CG34: 0.5 | CJ34: 0 | CM34: 0
A35: 07:00 - 07:15 | D35: 0 | E35: 0 | G35: 0 | J35: 0 | K35: 0 | M35: 0 | N35: 0 | P35: 0 | Q35: 0 | S35: 0 | T35: 0 | V35: 0 | W35: 0 | Y35: 0 | Z35: 0 | AB35: 0 | AC35: 0 | AE35: 0 | AH35: 0.5 | AI35: 0 | AK35: 0 | AL35: 0.6 | AN35: 0 | AO35: 0 | AQ35: 0 | AR35: 0 | AT35: 0 | AU35: 0 | AW35: 0 | AX35: 0 | AZ35: 0 | BA35: 0 | BC35: 0 | BD35: 0 | BF35: 0 | BG35: 0 | BI35: 0 | BJ35: 0 | BL35: 0 | BM35: 0 | BO35: 0 | BP35: 0 | BR35: 0 | BS35: 0 | BU35: 0 | BV35: 0 | BX35: 0 | CA35: 0 | CD35: 0 | CG35: 0 | CJ35: 0 | CM35: 0
A36: 07:15 - 07:30 | D36: 0 | E36: 0 | G36: 0 | J36: 0 | K36: 0 | M36: 0 | N36: 0 | P36: 0 | Q36: 0 | S36: 0 | T36: 0 | V36: 0 | W36: 0 | Y36: 0 | Z36: 0 | AB36: 0 | AC36: 0 | AE36: 0 | AH36: 0 | AI36: 0 | AK36: 0 | AL36: 0.6 | AN36: 0 | AO36: 0 | AQ36: 0 | AR36: 0 | AT36: 0 | AU36: 0 | AW36: 0 | AX36: 0 | AZ36: 0 | BA36: 0 | BC36: 0 | BD36: 0 | BF36: 0 | BG36: 0 | BI36: 0 | BJ36: 0 | BL36: 0 | BM36: 0 | BO36: 0 | BP36: 0 | BR36: 0 | BS36: 0 | BU36: 0 | BV36: 0 | BX36: 0 | CA36: 0 | CD36: 0 | CG36: 0 | CJ36: 0 | CM36: 0
A37: 07:30 - 07:45 | D37: 0 | E37: 0 | G37: 0 | J37: 0 | K37: 0 | M37: 0 | N37: 0 | P37: 0 | Q37: 0 | S37: 0 | T37: 0 | V37: 0 | W37: 0 | Y37: 0 | Z37: 0 | AB37: 0 | AC37: 0 | AE37: 0 | AH37: 0 | AI37: 0 | AK37: 0 | AL37: 0.6 | AN37: 0 | AO37: 0 | AQ37: 0 | AR37: 0 | AT37: 0 | AU37: 0 | AW37: 0 | AX37: 0 | AZ37: 0 | BA37: 0 | BC37: 0 | BD37: 0 | BF37: 0 | BG37: 0 | BI37: 0 | BJ37: 0 | BL37: 0 | BM37: 0 | BO37: 0 | BP37: 0 | BR37: 0 | BS37: 0 | BU37: 0 | BV37: 0 | BX37: 0 | CA37: 0 | CD37: 0 | CG37: 0 | CJ37: 0 | CM37: 0
A38: 07:45 - 08:00 | D38: 0 | E38: 0 | G38: 0 | J38: 0 | K38: 0 | M38: 0 | N38: 0 | P38: 0 | Q38: 0 | S38: 0 | T38: 0 | V38: 0 | W38: 0 | Y38: 0 | Z38: 0 | AB38: 0 | AC38: 0 | AE38: 0 | AH38: 0 | AI38: 0 | AK38: 0 | AL38: 0 | AN38: 0 | AO38: 0 | AQ38: 0 | AR38: 0 | AT38: 0 | AU38: 0 | AW38: 0 | AX38: 0 | AZ38: 0 | BA38: 0 | BC38: 0 | BD38: 0 | BF38: 0 | BG38: 0 | BI38: 0 | BJ38: 0 | BL38: 0 | BM38: 0 | BO38: 0 | BP38: 0 | BR38: 0 | BS38: 0 | BU38: 0 | BV38: 0 | BX38: 0 | CA38: 0 | CD38: 0 | CG38: 0 | CJ38: 0 | CM38: 0
A39: 08:00 - 08:15 | D39: 0 | E39: 0 | G39: 0 | J39: 0 | K39: 0.5 | M39: 0 | N39: 0 | P39: 0 | Q39: 0 | S39: 0 | T39: 0 | V39: 0 | W39: 0 | Y39: 0 | Z39: 0 | AB39: 0 | AC39: 0 | AE39: 0 | AH39: 0 | AI39: 0 | AK39: 0 | AL39: 0 | AN39: 0 | AO39: 0 | AQ39: 0 | AR39: 0 | AT39: 0 | AU39: 0 | AW39: 0 | AX39: 0 | AZ39: 0 | BA39: 0 | BC39: 0 | BD39: 0 | BF39: 0 | BG39: 0 | BI39: 0 | BJ39: 0 | BL39: 0 | BM39: 0 | BO39: 0 | BP39: 0 | BR39: 0 | BS39: 0 | BU39: 0 | BV39: 0 | BX39: 0 | CA39: 0 | CD39: 0 | CG39: 0 | CJ39: 0 | CM39: 0
A40: 08:15 - 08:30 | D40: 0 | E40: 0 | G40: 0 | J40: 0 | K40: 0.5 | M40: 0 | N40: 0 | P40: 0 | Q40: 0 | S40: 0 | T40: 0 | V40: 0 | W40: 0 | Y40: 0 | Z40: 0 | AB40: 0 | AC40: 0 | AE40: 0 | AH40: 0 | AI40: 0 | AK40: 0 | AL40: 0 | AN40: 0 | AO40: 0 | AQ40: 0 | AR40: 0 | AT40: 0 | AU40: 0 | AW40: 0 | AX40: 0 | AZ40: 0 | BA40: 0 | BC40: 0 | BD40: 0 | BF40: 0 | BG40: 0 | BI40: 0 | BJ40: 0 | BL40: 0 | BM40: 0 | BO40: 0 | BP40: 0 | BR40: 0 | BS40: 0 | BU40: 0 | BV40: 0 | BX40: 0 | CA40: 0 | CD40: 0 | CG40: 0 | CJ40: 0 | CM40: 0
A41: 08:30 - 08:45 | D41: 0 | E41: 0 | G41: 0 | J41: 0 | K41: 0 | M41: 0 | N41: 0 | P41: 0 | Q41: 0 | S41: 0 | T41: 0 | V41: 0 | W41: 0 | Y41: 0 | Z41: 0 | AB41: 0 | AC41: 0 | AE41: 0 | AH41: 0 | AI41: 0 | AK41: 0 | AL41: 0 | AN41: 0 | AO41: 0 | AQ41: 0 | AR41: 0 | AT41: 0 | AU41: 0 | AW41: 0 | AX41: 0 | AZ41: 0 | BA41: 0 | BC41: 0 | BD41: 0 | BF41: 0 | BG41: 0 | BI41: 0 | BJ41: 0 | BL41: 0 | BM41: 0 | BO41: 0 | BP41: 0 | BR41: 0 | BS41: 0 | BU41: 0 | BV41: 0 | BX41: 0 | CA41: 0 | CD41: 0 | CG41: 0 | CJ41: 0 | CM41: 0
A42: 08:45 - 09:00 | D42: 0 | E42: 0 | G42: 0 | J42: 0 | K42: 0 | M42: 0 | N42: 0 | P42: 0 | Q42: 0 | S42: 0 | T42: 0 | V42: 0 | W42: 0 | Y42: 0 | Z42: 0 | AB42: 0 | AC42: 0 | AE42: 0 | AH42: 0 | AI42: 0 | AK42: 0 | AL42: 0 | AN42: 0 | AO42: 0 | AQ42: 0 | AR42: 0 | AT42: 0 | AU42: 0 | AW42: 0 | AX42: 0 | AZ42: 0 | BA42: 0 | BC42: 0 | BD42: 0 | BF42: 0 | BG42: 0 | BI42: 0 | BJ42: 0 | BL42: 0 | BM42: 0 | BO42: 0 | BP42: 0 | BR42: 0 | BS42: 0 | BU42: 0 | BV42: 0 | BX42: 0 | CA42: 0 | CD42: 0 | CG42: 0 | CJ42: 0 | CM42: 0
A43: 09:00 - 09:15 | D43: 0 | E43: 0 | G43: 0 | J43: 0 | K43: 0 | M43: 0 | N43: 0 | P43: 0 | Q43: 0 | S43: 0 | T43: 0 | V43: 0 | W43: 0 | Y43: 0 | Z43: 0 | AB43: 0 | AC43: 0 | AE43: 0 | AH43: 0 | AI43: 0 | AK43: 0 | AL43: 0 | AN43: 0 | AO43: 0 | AQ43: 0 | AR43: 0 | AT43: 0 | AU43: 0 | AW43: 0 | AX43: 0 | AZ43: 0 | BA43: 0 | BC43: 0 | BD43: 0 | BF43: 0 | BG43: 0 | BI43: 0 | BJ43: 0 | BL43: 0 | BM43: 0.7 | BO43: 0 | BP43: 0.7 | BR43: 0 | BS43: 0 | BU43: 0 | BV43: 0 | BX43: 0 | CA43: 0 | CD43: 0 | CG43: 0 | CJ43: 0 | CM43: 0
... A46: 09:45 - 10:00 | D46: 0 | E46: 0 | G46: 0 | J46: 0 | K46: 0 | M46: 0 | N46: 0 | P46: 0 | Q46: 0 | S46: 0 | T46: 0 | V46: 0 | W46: 0 | Y46: 0 | Z46: 0 | AB46: 0 | AC46: 0 | AE46: 0 | AH46: 0 | AI46: 0 | AK46: 0 | AL46: 0 | AN46: 0 | AO46: 0 | AQ46: 0 | AR46: 0 | AT46: 0 | AU46: 0 | AW46: 0 | AX46: 0 | AZ46: 0 | BA46: 0 | BC46: 0 | BD46: 0.6 | BF46: 0 | BG46: 0 | BI46: 0 | BJ46: 0 | BL46: 0 | BM46: 0 | BO46: 0 | BP46: 0 | BR46: 0 | BS46: 0 | BU46: 0 | BV46: 0 | BX46: 0 | CA46: 0 | CD46: 0 | CG46: 0 | CJ46: 0 | CM46: 0
A47: 10:00 - 10:15 | B47: C4 | D47: 0 | E47: 0 | G47: 0 | J47: 0 | K47: 0 | M47: 0 | N47: 0 | P47: 0 | Q47: 0 | S47: 0 | T47: 0 | V47: 0 | W47: 0 | Y47: 0 | Z47: 0 | AB47: 0 | AC47: 0 | AE47: 0 | AH47: 0 | AI47: 0 | AK47: 0 | AL47: 0 | AN47: 0 | AO47: 0 | AQ47: 0 | AR47: 0 | AT47: 0 | AU47: 0 | AW47: 0 | AX47: 0 | AZ47: 0 | BA47: 0 | BC47: 0 | BD47: 0 | BF47: 0 | BG47: 0 | BI47: 0 | BJ47: 0 | BL47: 0 | BM47: 0 | BO47: 0 | BP47: 0 | BR47: 0 | BS47: 0 | BU47: 0 | BV47: 0 | BX47: 0 | CA47: 0 | CD47: 0 | CG47: 0 | CJ47: 0 | CM47: 0
A48: 10:15 - 10:30 | D48: 0 | E48: 0 | G48: 0 | J48: 0 | K48: 0 | M48: 0 | N48: 0 | P48: 0 | Q48: 0 | S48: 0 | T48: 0 | V48: 0 | W48: 0 | Y48: 0 | Z48: 0 | AB48: 0 | AC48: 0 | AE48: 0 | AH48: 0 | AI48: 0 | AK48: 0 | AL48: 2.6 | AN48: 0 | AO48: 0 | AQ48: 0 | AR48: 0 | AT48: 0 | AU48: 0 | AW48: 0 | AX48: 0 | AZ48: 0 | BA48: 0 | BC48: 0 | BD48: 0 | BF48: 0 | BG48: 0 | BI48: 0 | BJ48: 0 | BL48: 0 | BM48: 0 | BO48: 0 | BP48: 0 | BR48: 0 | BS48: 0 | BU48: 0 | BV48: 0 | BX48: 0 | CA48: 0 | CD48: 0 | CG48: 0 | CJ48: 0 | CM48: 0
...

Sheet Savings Sheet
A1: IEX POWER PURCHASE, DELIVERY AND COST SHEET
A2: DATE | B2: LINE LOSS % | C2: IEX Price | D2: Equivalent EB Price | E2: Total Cost Saving | F2: IEX Price per Unit | G2: Equivalent EB Price per Unit | H2: Cost Saving Per Unit | I2: Tata Power Bill
B3: CT
A4: 44896 | B4: ='Energy Schedule'!D3 -> 0.0343 | C4: ='01'!$B$44 -> 110442.82 | D4: ='01'!$B$46 -> 155363.77 | E4: =D4-C4 -> 44920.954 | F4: ='01'!$B$45 -> 6.9237573 | G4: ='01'!$B$47 -> 9.7398913 | H4: =G4-F4 -> 2.8161341
A5: =A4+1 -> 44897 | B5: ='Energy Schedule'!G3 -> 0.0343 | C5: ='02'!$B$44 -> 91934.959 | D5: ='02'!$B$46 -> 113273.19 | E5: =D5-C5 -> 21338.23 | F5: ='02'!$B$45 -> 7.9536069 | G5: ='02'!$B$47 -> 9.79965 | H5: =G5-F5 -> 1.8460431
A6: =A5+1 -> 44898 | B6: ='Energy Schedule'!J3 -> 0.0343 | C6: ='03'!$B$44 -> 99210.45 | D6: ='03'!$B$46 -> 122016.27 | E6: =D6-C6 -> 22805.82 | F6: ='03'!$B$45 -> 8.3314254 | G6: ='03'!$B$47 -> 10.246597 | H6: =G6-F6 -> 1.9151711
A7: =A6+1 -> 44899 | B7: ='Energy Schedule'!M3 -> 0.0343 | C7: ='04'!$B$44 -> 180092.63 | D7: ='04'!$B$46 -> 217210.11 | E7: =D7-C7 -> 37117.479 | F7: ='04'!$B$45 -> 8.3317795 | G7: ='04'!$B$47 -> 10.048977 | H7: =G7-F7 -> 1.7171977
A8: =A7+1 -> 44900 | B8: ='Energy Schedule'!P3 -> 0.0361 | C8: ='05'!$B$44 -> 105620.59 | D8: ='05'!$B$46 -> 129949.28 | E8: =D8-C8 -> 24328.691 | F8: ='05'!$B$45 -> 8.3224196 | G8: ='05'!$B$47 -> 10.239409 | H8: =G8-F8 -> 1.9169895
A9: =A8+1 -> 44901 | B9: ='Energy Schedule'!S3 -> 0.0361 | C9: ='06'!$B$44 -> 124711.24 | D9: ='06'!$B$46 -> 147454.34 | E9: =D9-C9 -> 22743.096 | F9: ='06'!$B$45 -> 8.5788436 | G9: ='06'!$B$47 -> 10.143333 | H9: =G9-F9 -> 1.5644897
A10: =A9+1 -> 44902 | B10: ='Energy Schedule'!V3 -> 0.0361 | C10: ='07'!$B$44 -> 106544.89 | D10: ='07'!$B$46 -> 128532.4 | E10: =D10-C10 -> 21987.517 | F10: ='07'!$B$45 -> 8.3256173 | G10: ='07'!$B$47 -> 10.043763 | H10: =G10-F10 -> 1.7181458
A11: =A10+1 -> 44903 | B11: ='Energy Schedule'!Y3 -> 0.0361 | C11: ='08'!$B$44 -> 152711.99 | D11: ='08'!$B$46 -> 176955.5 | E11: =D11-C11 -> 24243.512 | F11: ='08'!$B$45 -> 8.7080966 | G11: ='07'!$B$47 -> 10.043763 | H11: =G11-F11 -> 1.3356664
A12: =A11+1 -> 44904 | B12: ='Energy Schedule'!AB3 -> 0.0361 | C12: ='09'!$B$44 -> 155993.7 | D12: ='09'!$B$46 -> 186222.88 | E12: =D12-C12 -> 30229.187 | F12: ='09'!$B$45 -> 8.4716471 | G12: ='09'!$B$47 -> 10.113322 | H12: =G12-F12 -> 1.6416753
A13: =A12+1 -> 44905 | B13: ='Energy Schedule'!AE3 -> 0.0361 | C13: ='10'!$B$44 -> 131820.36 | D13: ='10'!$B$46 -> 158729.65 | E13: =D13-C13 -> 26909.296 | F13: ='10'!$B$45 -> 8.3397994 | G13: ='10'!$B$47 -> 10.042254 | H13: =G13-F13 -> 1.7024543
A14: =A13+1 -> 44906 | B14: ='Energy Schedule'!AH3 -> 0.0361 | C14: ='11'!$B$44 -> 249454.18 | D14: ='11'!$B$46 -> 308881.83 | E14: =D14-C14 -> 59427.653 | F14: ='11'!$B$45 -> 7.8967979 | G14: ='11'!$B$47 -> 9.7780579 | H14: =G14-F14 -> 1.88126
A15: =A14+1 -> 44907 | B15: ='Energy Schedule'!AK3 -> 0.0382 | C15: ='12'!$B$44 -> 167305.32 | D15: ='12'!$B$46 -> 206223.23 | E15: =D15-C15 -> 38917.911 | F15: ='12'!$B$45 -> 8.2426844 | G15: ='12'!$B$47 -> 10.160065 | H15: =G15-F15 -> 1.9173811
A16: =A15+1 -> 44908 | B16: ='Energy Schedule'!AN3 -> 0.0382 | C16: ='13'!$B$44 -> 144289.11 | D16: ='13'!$B$46 -> 179658.71 | E16: =D16-C16 -> 35369.598 | F16: ='13'!$B$45 -> 7.8906087 | G16: ='13'!$B$47 -> 9.8248341 | H16: =G16-F16 -> 1.9342254
A17: =A16+1 -> 44909 | B17: ='Energy Schedule'!AQ3 -> 0.0382 | C17: ='14'!$B$44 -> 130856.25 | D17: ='14'!$B$46 -> 161574.2 | E17: =D17-C17 -> 30717.945 | F17: ='14'!$B$45 -> 8.0289509 | G17: ='14'!$B$47 -> 9.9137128 | H17: =G17-F17 -> 1.8847619
A18: =A17+1 -> 44910 | B18: ='Energy Schedule'!AT3 -> 0.0382 | C18: ='15'!$B$44 -> 117683.51 | D18: ='15'!$B$46 -> 141214.94 | E18: =D18-C18 -> 23531.432 | F18: ='15'!$B$45 -> 8.2199272 | G18: ='15'!$B$47 -> 9.8635445 | H18: =G18-F18 -> 1.6436174
A19: =A18+1 -> 44911 | B19: ='Energy Schedule'!AW3 -> 0.0382 | C19: ='16'!$B$44 -> 61948.302 | D19: ='16'!$B$46 -> 73483.144 | E19: =D19-C19 -> 11534.843 | F19: ='16'!$B$45 -> 8.426665 | G19: ='16'!$B$47 -> 9.9957193 | H19: =G19-F19 -> 1.5690544
A20: =A19+1 -> 44912 | B20: ='Energy Schedule'!AZ3 -> 0.0382 | C20: ='17'!$B$44 -> 76854.303 | D20: ='17'!$B$46 -> 91670.816 | E20: =D20-C20 -> 14816.512 | F20: ='17'!$B$45 -> 8.2349863 | G20: ='17'!$B$47 -> 9.8225848 | H20: =G20-F20 -> 1.5875985
A21: =A20+1 -> 44913 | B21: ='Energy Schedule'!BC3 -> 0.0382 | C21: ='18'!$B$44 -> 146296.21 | D21: ='18'!$B$46 -> 170745.41 | E21: =D21-C21 -> 24449.191 | F21: ='18'!$B$45 -> 8.728679 | G21: ='18'!$B$47 -> 10.187426 | H21: =G21-F21 -> 1.4587468
A22: =A21+1 -> 44914 | B22: ='Energy Schedule'!BF3 -> 0.0418 | C22: ='19'!$B$44 -> 79100.029 | D22: ='19'!$B$46 -> 94414.957 | E22: =D22-C22 -> 15314.928 | F22: ='19'!$B$45 -> 8.4693234 | G22: ='19'!$B$47 -> 10.109109 | H22: =G22-F22 -> 1.6397855
A23: =A22+1 -> 44915 | B23: ='Energy Schedule'!BI3 -> 0.0418 | C23: ='20'!$B$44 -> 62783.116 | D23: ='20'!$B$46 -> 77197.019 | E23: =D23-C23 -> 14413.904 | F23: ='20'!$B$45 -> 8.2546832 | G23: ='20'!$B$47 -> 10.149814 | H23: =G23-F23 -> 1.8951307
A24: =A23+1 -> 44916 | B24: ='Energy Schedule'!BL3 -> 0.0418 | C24: ='21'!$B$44 -> 119433.33 | D24: ='21'!$B$46 -> 143004.82 | E24: =D24-C24 -> 23571.491 | F24: ='21'!$B$45 -> 8.2528633 | G24: ='21'!$B$47 -> 9.8816573 | H24: =G24-F24 -> 1.628794
A25: =A24+1 -> 44917 | B25: ='Energy Schedule'!BO3 -> 0.0418 | C25: ='22'!$B$44 -> 105283.13 | D25: ='22'!$B$46 -> 143706.33 | E25: =D25-C25 -> 38423.201 | F25: ='22'!$B$45 -> 7.2519131 | G25: ='22'!$B$47 -> 9.8985072 | H25: =G25-F25 -> 2.6465941
A26: =A25+1 -> 44918 | B26: ='Energy Schedule'!BR3 -> 0.0418 | C26: ='23'!$B$44 -> 81463.005 | D26: ='23'!$B$46 -> 101791.13 | E26: =D26-C26 -> 20328.12 | F26: ='23'!$B$45 -> 8.1007384 | G26: ='23'!$B$47 -> 10.122181 | H26: =G26-F26 -> 2.0214426
A27: =A26+1 -> 44919 | B27: ='Energy Schedule'!BU3 -> 0.0418 | C27: ='24'!$B$44 -> 116234.81 | D27: ='24'!$B$46 -> 142963.56 | E27: =D27-C27 -> 26728.749 | F27: ='24'!$B$45 -> 7.8049284 | G27: ='24'!$B$47 -> 9.5997089 | H27: =G27-F27 -> 1.7947806
A28: =A27+1 -> 44920 | B28: ='Energy Schedule'!BX3 -> 0.0418 | C28: ='25'!$B$44 -> 95686.671 | D28: ='25'!$B$46 -> 117306.87 | E28: =D28-C28 -> 21620.199 | F28: ='25'!$B$45 -> 7.9751256 | G28: ='25'!$B$47 -> 9.7770882 | H28: =G28-F28 -> 1.8019626
A29: =A28+1 -> 44921 | B29: ='Energy Schedule'!CA3 -> 0.0419 | C29: ='26'!$B$44 -> 46558.265 | D29: ='26'!$B$46 -> 60092.562 | E29: =D29-C29 -> 13534.297 | F29: ='26'!$B$45 -> 7.8978712 | G29: ='26'!$B$47 -> 10.19375 | H29: =G29-F29 -> 2.2958788
A30: =A29+1 -> 44922 | B30: ='Energy Schedule'!CD3 -> 0.0419 | C30: ='27'!$B$44 -> 49825.652 | D30: ='27'!$B$46 -> 61970.132 | E30: =D30-C30 -> 12144.48 | F30: ='27'!$B$45 -> 8.1950325 | G30: ='27'!$B$47 -> 10.192486 | H30: =G30-F30 -> 1.9974532
A31: =A30+1 -> 44923 | B31: ='Energy Schedule'!CG3 -> 0.0419 | C31: ='28'!$B$44 -> 60472.879 | D31: ='28'!$B$46 -> 76155.071 | E31: =D31-C31 -> 15682.192 | F31: ='28'!$B$45 -> 8.2259671 | G31: ='28'!$B$47 -> 10.359175 | H31: =G31-F31 -> 2.1332074
A32: =A31+1 -> 44924 | B32: ='Energy Schedule'!CJ3 -> 0.0419 | C32: ='29'!$B$44 -> 40971.879 | D32: ='29'!$B$46 -> 50735.66 | E32: =D32-C32 -> 9763.7802 | F32: ='29'!$B$45 -> 8.1673204 | G32: ='29'!$B$47 -> 10.113629 | H32: =G32-F32 -> 1.9463086
A33: =A32+1 -> 44925 | B33: ='Energy Schedule'!CM3 -> 0.0419 | C33: ='30'!$B$44 -> 57357.129 | D33: ='30'!$B$46 -> 70078.759 | E33: =D33-C33 -> 12721.63 | F33: ='30'!$B$45 -> 8.4968508 | G33: ='30'!$B$47 -> 10.381426 | H33: =G33-F33 -> 1.8845747
A34: =A33+1 -> 44926 | B34: ='Energy Schedule'!CP3 -> 0 | C34: ='31'!$B$44 -> 0 | D34: ='31'!$B$46 -> 0 | E34: =D34-C34 -> 0 | F34: ='31'!$B$45 -> #DIV/0! | G34: ='31'!$B$47 -> #DIV/0! | H34: =G34-F34 -> #DIV/0!
A35: Total | C35: =SUM(C4:C34) -> 3268940.7 | D35: =SUM(D4:D34) -> 4008576.5 | E35: =SUM(E4:E34) -> 739635.84 | F35: =AVERAGE(F4:F34) -> #DIV/0! | G35: =D35/#REF! -> #REF! | H35: =G35-F35 -> #REF!

Sheet Slot Wise Consolidate
A4: TNEB Slot | B4: IEX Allotment | C4: Consumption | D4: Balance
A5: C1 | B5: =SUM('01:31'!I6) -> 9683.9895 | C5: =SUM('01:31'!J6) -> 54900 | D5: =SUM('01:31'!K6) -> 45216.011
A6: C2 | B6: =SUM('01:31'!I7) -> 198750.18 | C6: =SUM('01:31'!J7) -> 274200 | D6: =SUM('01:31'!K7) -> 75449.823
A7: C4 | B7: =SUM('01:31'!I8) -> 112762.39 | C7: =SUM('01:31'!J8) -> 512800 | D7: =SUM('01:31'!K8) -> 400037.61
A8: C5 | B8: =SUM('01:31'!I9) -> 79826.454 | C8: =SUM('01:31'!J9) -> 104900 | D8: =SUM('01:31'!K9) -> 25073.546

Sheet Consumption Details
A2: Date | B2: C1 | C2: C2 | D2: C4 | E2: C5
A3: 44896 | B3: 1500 | C3: 9300 | D3: 18300 | E3: 5150
A4: =A3+1 -> 44897 | B4: 2050 | C4: 10000 | D4: 19250 | E4: 3650
A5: =A4+1 -> 44898 | B5: 1800 | C5: 10650 | D5: 20350 | E5: 3800
A6: =A5+1 -> 44899 | B6: 2050 | C6: 10600 | D6: 21850 | E6: 3750
A7: =A6+1 -> 44900 | B7: 1950 | C7: 9300 | D7: 19400 | E7: 3400
A8: =A7+1 -> 44901 | B8: 1850 | C8: 9050 | D8: 17550 | E8: 3350
A9: =A8+1 -> 44902 | B9: 1950 | C9: 9450 | D9: 17950 | E9: 3200
A10: =A9+1 -> 44903 | B10: 1800 | C10: 9100 | D10: 17800 | E10: 3400
A11: =A10+1 -> 44904 | B11: 1550 | C11: 8950 | D11: 18050 | E11: 3550
A12: =A11+1 -> 44905 | B12: 2300 | C12: 9350 | D12: 20250 | E12: 3650
A13: =A12+1 -> 44906 | B13: 2000 | C13: 10850 | D13: 20650 | E13: 3650
A14: =A13+1 -> 44907 | B14: 2700 | C14: 9150 | D14: 15600 | E14: 3200
A15: =A14+1 -> 44908 | B15: 1750 | C15: 9150 | D15: 18400 | E15: 3300
... A30: =A29+1 -> 44923 | B30: 1900 | C30: 10450 | D30: 20600 | E30: 4050
A31: =A30+1 -> 44924
A32: =A31+1 -> 44925
A33: =A32+1 -> 44926

Sheet 01
C2: G-DAM | D2: DAM | E2: RTM
A3: Unit Purchased in MWh | C3: 0 | D3: ='Energy Schedule'!D103 -> 12 | E3: ='Energy Schedule'!E103 -> 5.25
A4: IEX Payout | C4: ='Energy Schedule'!C5 -> 0 | D4: ='Energy Schedule'!D5 -> 45070.355 | E4: ='Energy Schedule'!E5 -> 3103.11
A5: Total Units in kWh | C5: =C3*1000 -> 0 | D5: =D3*1000 -> 12000 | E5: =E3*1000 -> 5250 | I5: IEX Delivered | J5: Consumption | K5: Balance
A6: CTU | B6: ='Energy Schedule'!D3 -> 0.0343 | C6: =C5-(C5*$B$6) -> 0 | D6: =D5-(D5*$B$6) -> 11588.4 | E6: =E5-(E5*$B$6) -> 5069.925 | H6: C1 | I6: =D33 -> 0 | J6: ='Consumption Details'!$B3 -> 1500 | K6: =J6-I6 -> 1500
A7: STU | B7: ='TNEB Charges'!B1 -> 0.0234 | C7: =C6-(C6*$B$7) -> 0 | D7: =D6-(D6*$B$7) -> 11317.231 | E7: =E6-(E6*$B$7) -> 4951.2888 | H7: C2 | I7: =D34 -> 6935.3409 | J7: ='Consumption Details'!$C3 -> 9300 | K7: =J7-I7 -> 2364.6591
A8: Discom Losses | B8: ='TNEB Charges'!B2 -> 0.0195 | C8: =C7-(C7*$B$8) -> 0 | D8: =D7-(D7*$B$8) -> 11096.545 | E8: =E7-(E7*$B$8) -> 4854.7386 | H8: C4 | I8: =D35 -> 3467.6704 | J8: ='Consumption Details'!$D3 -> 18300 | K8: =J8-I8 -> 14832.33
A9: Delivered @ Bus | C9: =C8 -> 0 | D9: =D8 -> 11096.545 | E9: =E8 -> 4854.7386 | H9: C5 | I9: =D36 -> 5548.2727 | J9: ='Consumption Details'!$E3 -> 5150 | K9: =J9-I9 -> -398.27271
A10: IEX Payout / Unit | C10: =C4/C9 -> #DIV/0! | D10: =D4/D9 -> 4.0616564 | E10: =E4/E9 -> 0.63919198 | K10: =J10-I10 -> 0
A11: IEX Transaction Charges | B11: ='TNEB Charges'!B5 -> 0.02 | C11: =(C3*1000*$B$11)+(C3*1000*$B$11*18%) -> 0 | D11: =(D3*1000*$B$11)+(D3*1000*$B$11*18%) -> 283.2 | E11: =(E3*1000*$B$11)+(E3*1000*$B$11*18%) -> 123.9
A12: NLDC Application fee | C12: ='Energy Schedule'!C$6 -> 0 | D12: ='Energy Schedule'!D$6 -> 9.09 | E12: ='Energy Schedule'!E$6 -> 13.7
A13: CTU Transmission Charges | B13: ='TNEB Charges'!B7 -> 457.6 | C13: =C3*$B$13 -> 0 | D13: =D3*$B$13 -> 5491.2 | E13: =E3*$B$13 -> 2402.4
A14: NLDC Sched & Oprn Charges | B14: ='TNEB Charges'!B8 -> 1 | C14: =C3*$B$14 -> 0 | D14: =D3*$B$14 -> 12 | E14: =E3*$B$14 -> 5.25
A15: STU Transmission Charges | B15: ='TNEB Charges'!B9 -> 260 | C15: =C3*$B$15 -> 0 | D15: =D3*$B$15 -> 3120 | E15: =E3*$B$15 -> 1365
A16: STU Scheduling | B16: ='TNEB Charges'!B10 -> 170 | C16: =IF(C3>0,$B$16,0) -> 0 | D16: =IF(D3>0,$B$16,0) -> 170 | E16: =IF(E3>0,$B$16,0) -> 170
A17: STU System Operating Charge | B17: ='TNEB Charges'!B11 -> 33.74 | C17: =C3*$B$17/24 -> 0 | D17: =D3*$B$17/24 -> 16.87 | E17: =E3*$B$17/24 -> 7.380625
A18: TPTCL Margin | B18: ='TNEB Charges'!B12 -> 0.02 | C18: =C3*$B$18*1000 -> 0 | D18: =D3*$B$18*1000 -> 240 | E18: =E3*$B$18*1000 -> 105
A19: CSS | B19: ='TNEB Charges'!B13 -> 1.99 | C19: =C9*$B$19 -> 0 | D19: =D9*$B$19 -> 22082.125 | E19: =E9*$B$19 -> 9660.9299
A20: ASC | B20: ='TNEB Charges'!B14 -> 0 | C20: =C9*$B$20 -> 0 | D20: =D9*$B$20 -> 0 | E20: =E9*$B$20 -> 0
A21: Wheeling Charges | B21: ='TNEB Charges'!B15 -> 1.04 | C21: =C8*$B$21 -> 0 | D21: =D8*$B$21 -> 11540.407 | E21: =E8*$B$21 -> 5048.9282
A22: E-Tax | B22: ='TNEB Charges'!B16 -> 0 | C22: =C9*$B$22 -> 0 | D22: =D9*$B$22 -> 0 | E22: =E9*$B$22 -> 0
A23: Solar RPO Charges | B23: ='TNEB Charges'!B17 -> 0.12 | C23: 0 | D23: =D9*$B$23*10.5% -> 139.81647 | E23: =E9*$B$23*10.5% -> 61.169707
A24: Non-Solar RPO Charges | B24: ='TNEB Charges'!B18 -> 0.12 | C24: 0 | D24: =D9*$B$24*10.5% -> 139.81647 | E24: =E9*$B$24*10.5% -> 61.169707
A25: Total Statutory Charges | C25: =SUM(C11:C24) -> 0 | D25: =SUM(D11:D24) -> 43244.526 | E25: =SUM(E11:E24) -> 19024.828
C26: =C25/C9 -> #DIV/0! | D26: =D25/D9 -> 3.8971161 | E26: =E25/E9 -> 3.9188161
A27: Total Cost incurred in IEX Purchase | C27: =C4+C25 -> 0 | D27: =D4+D25 -> 88314.881 | E27: =E4+E25 -> 22127.938
A28: Cost per Unit incurred | C28: =C27/C9 -> #DIV/0! | D28: =D27/D9 -> 7.9587725 | E28: =E27/E9 -> 4.5580081
I29: Slot | J29: Morning peak | K29: Evening peak | L29: Normal hour | M29: Normal hour | N29: Night Hour | O29: RTC
A30: EQUIVALENT EB PRICE TO THE UNITS PURCHASED FROM IEX | J30: C1 | K30: C2 | L30: C4 | M30: C5 | N30: C24
A31: DAM | I31: TNEB Tariff | J31: =$L$31+($L$31*25%) -> 10.625 | K31: =$L$31+($L$31*25%) -> 10.625 | L31: 8.5 | M31: =$L$31-($L$31*5%) -> 8.075 | N31: 6.03 | O31: =AVERAGE(J31:M31) -> 9.45625
A32: Slot | B32: Price | C32: Purchase | D32: Delivered | E32: EB Cost | I32: E-Tax | J32: 0.05 | K32: 0.05 | L32: 0.05 | M32: 0.05 | N32: 0.05 | O32: 0.05
A33: C1 | B33: =J33 -> 11.15625 | C33: =J39+J46+J53 -> 0 | D33: =M39+M46+M53 -> 0 | E33: =D33*B33 -> 0 | I33: Total price/Unit | J33: =J31+(J31*J32) -> 11.15625 | K33: =K31+(K31*K32) -> 11.15625 | L33: =L31+(L31*L32) -> 8.925 | M33: =M31+(M31*M32) -> 8.47875 | N33: =N31+(N31*N32) -> 6.3315 | O33: =AVERAGE(J33:M33) -> 9.9290625
A34: C2 | B34: =K33 -> 11.15625 | C34: =J41+J48+J55 -> 7500 | D34: =M41+M48+M55 -> 6935.3409 | E34: =D34*B34 -> 77372.397
A35: C4 | B35: =L33 -> 8.925 | C35: =J38+J40+J45+J47+J52+J54 -> 3750 | D35: =M38+M40+M45+M47+M52+M54 -> 3467.6704 | E35: =D35*B35 -> 30948.959
A36: C5 | B36: =M33 -> 8.47875 | C36: =J37+J42+J44+J49+J51+J56 -> 6000 | D36: =M37+M42+M44+M49+M51+M56 -> 5548.2727 | E36: =D36*B36 -> 47042.417 | I36: GDAM
A37: Total | C37: =SUM(C33:C36) -> 17250 | D37: =SUM(D33:D36) -> 15951.284 | E37: =SUM(E33:E36) -> 155363.77 | H37: C5 | I37: =SUM('Energy Schedule'!C7:C26)/4 -> 0 | J37: =I37*1000 -> 0 | K37: =J37-(J37*$B$6) -> 0 | L37: =K37-(K37*$B$7) -> 0 | M37: =L37-(L37*$B$8) -> 0
H38: C4 | I38: =SUM('Energy Schedule'!C27:C30)/4 -> 0 | J38: =I38*1000 -> 0 | K38: =J38-(J38*$B$6) -> 0 | L38: =K38-(K38*$B$7) -> 0 | M38: =L38-(L38*$B$8) -> 0
H39: C1 | I39: =SUM('Energy Schedule'!C31:C46)/4 -> 0 | J39: =I39*1000 -> 0 | K39: =J39-(J39*$B$6) -> 0 | L39: =K39-(K39*$B$7) -> 0 | M39: =L39-(L39*$B$8) -> 0
H40: C4 | I40: =SUM('Energy Schedule'!C47:C78)/4 -> 0 | J40: =I40*1000 -> 0 | K40: =J40-(J40*$B$6) -> 0 | L40: =K40-(K40*$B$7) -> 0 | M40: =L40-(L40*$B$8) -> 0
H41: C2 | I41: =SUM('Energy Schedule'!C79:C94)/4 -> 0 | J41: =I41*1000 -> 0 | K41: =J41-(J41*$B$6) -> 0 | L41: =K41-(K41*$B$7) -> 0 | M41: =L41-(L41*$B$8) -> 0
...

Sheet 02
C2: G-DAM | D2: DAM | E2: RTM
A3: Unit Purchased in MWh | C3: ='Energy Schedule'!F103 -> 0 | D3: ='Energy Schedule'!G103 -> 12.5 | E3: ='Energy Schedule'!H103 -> 0
A4: IEX Payout | C4: ='Energy Schedule'!F5 -> 0 | D4: ='Energy Schedule'!G$5 -> 46896.22 | E4: ='Energy Schedule'!H$5 -> 0
A5: Total Units in kWh | C5: =C3*1000 -> 0 | D5: =D3*1000 -> 12500 | E5: =E3*1000 -> 0 | I5: IEX Delivered | J5: Consumption | K5: Balance
A6: CTU | B6: ='Energy Schedule'!G3 -> 0.0343 | C6: =C5-(C5*$B$6) -> 0 | D6: =D5-(D5*$B$6) -> 12071.25 | E6: =E5-(E5*$B$6) -> 0 | H6: C1 | I6: =D33 -> 0 | J6: ='Consumption Details'!$B4 -> 2050 | K6: =J6-I6 -> 2050
A7: STU | B7: ='TNEB Charges'!B1 -> 0.0234 | C7: =C6-(C6*$B$7) -> 0 | D7: =D6-(D6*$B$7) -> 11788.783 | E7: =E6-(E6*$B$7) -> 0 | H7: C2 | I7: =D34 -> 5548.2727 | J7: ='Consumption Details'!$C4 -> 10000 | K7: =J7-I7 -> 4451.7273
A8: Discom Losses | B8: ='TNEB Charges'!B2 -> 0.0195 | C8: =C7-(C7*$B$8) -> 0 | D8: =D7-(D7*$B$8) -> 11558.901 | E8: =E7-(E7*$B$8) -> 0 | H8: C4 | I8: =D35 -> 924.71212 | J8: ='Consumption Details'!$D4 -> 19250 | K8: =J8-I8 -> 18325.288
A9: Delivered @ Bus | B9: ='TNEB Charges'!B3 -> 0 | C9: =C8 -> 0 | D9: =D8 -> 11558.901 | E9: =E8 -> 0 | H9: C5 | I9: =D36 -> 5085.9167 | J9: ='Consumption Details'!$E4 -> 3650 | K9: =J9-I9 -> -1435.9167
A10: IEX Payout / Unit | B10: ='TNEB Charges'!B4 -> 0 | C10: =C4/C9 -> #DIV/0! | D10: =D4/D9 -> 4.057152 | E10: =E4/E9 -> #DIV/0!
A11: IEX Transaction Charges | B11: ='TNEB Charges'!B5 -> 0.02 | C11: =(C3*1000*$B$11)+(C3*1000*$B$11*18%) -> 0 | D11: =(D3*1000*$B$11)+(D3*1000*$B$11*18%) -> 295 | E11: =(E3*1000*$B$11)+(E3*1000*$B$11*18%) -> 0
A12: NLDC Application fee | B12: ='TNEB Charges'!B6 -> 0 | C12: ='Energy Schedule'!F$6 -> 0 | D12: ='Energy Schedule'!G$6 -> 8.91 | E12: ='Energy Schedule'!H$6 -> 0
A13: CTU Transmission Charges | B13: ='TNEB Charges'!B7 -> 457.6 | C13: =C3*$B$13 -> 0 | D13: =D3*$B$13 -> 5720 | E13: =E3*$B$13 -> 0
A14: NLDC Sched & Oprn Charges | B14: ='TNEB Charges'!B8 -> 1 | C14: =C3*$B$14 -> 0 | D14: =D3*$B$14 -> 12.5 | E14: =E3*$B$14 -> 0
A15: STU Transmission Charges | B15: ='TNEB Charges'!B9 -> 260 | C15: =C3*$B$15 -> 0 | D15: =D3*$B$15 -> 3250 | E15: =E3*$B$15 -> 0
A16: STU Scheduling | B16: ='TNEB Charges'!B10 -> 170 | C16: =IF(C3>0,$B$16,0) -> 0 | D16: =IF(D3>0,$B$16,0) -> 170 | E16: =IF(E3>0,$B$16,0) -> 0
A17: STU System Operating Charge | B17: ='TNEB Charges'!B11 -> 33.74 | C17: =C3*$B$17/24 -> 0 | D17: =D3*$B$17/24 -> 17.572917 | E17: =E3*$B$17/24 -> 0
A18: TPTCL Margin | B18: ='TNEB Charges'!B12 -> 0.02 | C18: =C3*$B$18*1000 -> 0 | D18: =D3*$B$18*1000 -> 250 | E18: =E3*$B$18*1000 -> 0
A19: CSS | B19: ='TNEB Charges'!B13 -> 1.99 | C19: =C9*$B$19 -> 0 | D19: =D9*$B$19 -> 23002.214 | E19: =E9*$B$19 -> 0
A20: ASC | B20: ='TNEB Charges'!B14 -> 0 | C20: =C9*$B$20 -> 0 | D20: =D9*$B$20 -> 0 | E20: =E9*$B$20 -> 0
A21: Wheeling Charges | B21: ='TNEB Charges'!B15 -> 1.04 | C21: =C8*$B$21 -> 0 | D21: =D8*$B$21 -> 12021.258 | E21: =E8*$B$21 -> 0
A22: E-Tax | B22: ='TNEB Charges'!B16 -> 0 | C22: =C9*$B$22 -> 0 | D22: =D9*$B$22 -> 0 | E22: =E9*$B$22 -> 0
A23: Solar RPO Charges | B23: ='TNEB Charges'!B17 -> 0.12 | C23: 0 | D23: =D9*$B$23*10.5% -> 145.64216 | E23: =E9*$B$23*10.5% -> 0
A24: Non-Solar RPO Charges | B24: ='TNEB Charges'!B18 -> 0.12 | C24: 0 | D24: =D9*$B$24*10.5% -> 145.64216 | E24: =E9*$B$24*10.5% -> 0
A25: Total Statutory Charges | C25: =SUM(C11:C24) -> 0 | D25: =SUM(D11:D24) -> 45038.739 | E25: =SUM(E11:E24) -> 0
C26: =C25/C9 -> #DIV/0! | D26: =D25/D9 -> 3.8964549 | E26: =E25/E9 -> #DIV/0!
A27: Total Cost incurred in IEX Purchase | C27: =C4+C25 -> 0 | D27: =D4+D25 -> 91934.959 | E27: =E4+E25 -> 0
A28: Cost per Unit incurred | C28: =C27/C9 -> #DIV/0! | D28: =D27/D9 -> 7.9536069 | E28: =E27/E9 -> #DIV/0!
I29: Slot | J29: Morning peak | K29: Evening peak | L29: Normal hour | M29: Normal hour | N29: Night Hour | O29: RTC
A30: EQUIVALENT EB PRICE TO THE UNITS PURCHASED FROM IEX | J30: C1 | K30: C2 | L30: C4 | M30: C5 | N30: C24
A31: DAM | I31: TNEB Tariff | J31: =$L$31+($L$31*25%) -> 10.625 | K31: =$L$31+($L$31*25%) -> 10.625 | L31: 8.5 | M31: =$L$31-($L$31*5%) -> 8.075 | N31: 6.03 | O31: =AVERAGE(J31:M31) -> 9.45625
A32: Slot | B32: Price | C32: Purchase | D32: Delivered | E32: EB Cost | I32: E-Tax | J32: 0.05 | K32: 0.05 | L32: 0.05 | M32: 0.05 | N32: 0.05 | O32: 0.05
A33: C1 | B33: =J33 -> 11.15625 | C33: =J39+J46+J53 -> 0 | D33: =M39+M46+M53 -> 0 | E33: =D33*B33 -> 0 | I33: Total price/Unit | J33: =J31+(J31*J32) -> 11.15625 | K33: =K31+(K31*K32) -> 11.15625 | L33: =L31+(L31*L32) -> 8.925 | M33: =M31+(M31*M32) -> 8.47875 | N33: =N31+(N31*N32) -> 6.3315 | O33: =AVERAGE(J33:M33) -> 9.9290625
A34: C2 | B34: =K33 -> 11.15625 | C34: =J41+J48+J55 -> 6000 | D34: =M41+M48+M55 -> 5548.2727 | E34: =D34*B34 -> 61897.917
A35: C4 | B35: =L33 -> 8.925 | C35: =J38+J40+J45+J47+J52+J54 -> 1000 | D35: =M38+M40+M45+M47+M52+M54 -> 924.71212 | E35: =D35*B35 -> 8253.0557
A36: C5 | B36: =M33 -> 8.47875 | C36: =J37+J42+J44+J49+J51+J56 -> 5500 | D36: =M37+M42+M44+M49+M51+M56 -> 5085.9167 | E36: =D36*B36 -> 43122.216 | I36: GDAM
A37: Total | C37: =SUM(C33:C36) -> 12500 | D37: =SUM(D33:D36) -> 11558.901 | E37: =SUM(E33:E36) -> 113273.19 | H37: C5 | I37: =SUM('Energy Schedule'!F7:F26)/4 -> 0 | J37: =I37*1000 -> 0 | K37: =J37-(J37*$B$6) -> 0 | L37: =K37-(K37*$B$7) -> 0 | M37: =L37-(L37*$B$8) -> 0
H38: C4 | I38: =SUM('Energy Schedule'!F27:F30)/4 -> 0 | J38: =I38*1000 -> 0 | K38: =J38-(J38*$B$6) -> 0 | L38: =K38-(K38*$B$7) -> 0 | M38: =L38-(L38*$B$8) -> 0
H39: C1 | I39: =SUM('Energy Schedule'!F31:F46)/4 -> 0 | J39: =I39*1000 -> 0 | K39: =J39-(J39*$B$6) -> 0 | L39: =K39-(K39*$B$7) -> 0 | M39: =L39-(L39*$B$8) -> 0
H40: C4 | I40: =SUM('Energy Schedule'!F47:F78)/4 -> 0 | J40: =I40*1000 -> 0 | K40: =J40-(J40*$B$6) -> 0 | L40: =K40-(K40*$B$7) -> 0 | M40: =L40-(L40*$B$8) -> 0
H41: C2 | I41: =SUM('Energy Schedule'!F79:F94)/4 -> 0 | J41: =I41*1000 -> 0 | K41: =J41-(J41*$B$6) -> 0 | L41: =K41-(K41*$B$7) -> 0 | M41: =L41-(L41*$B$8) -> 0
...

Sheet 03
C2: G-DAM | D2: DAM | E2: RTM
A3: Unit Purchased in MWh | C3: ='Energy Schedule'!I$103 -> 0 | D3: ='Energy Schedule'!J$103 -> 9.25 | E3: ='Energy Schedule'!K$103 -> 3.6275
A4: IEX Payout | C4: ='Energy Schedule'!I$5 -> 0 | D4: ='Energy Schedule'!J$5 -> 38325.914 | E4: ='Energy Schedule'!K$5 -> 14307.76
A5: Total Units in kWh | C5: =C3*1000 -> 0 | D5: =D3*1000 -> 9250 | E5: =E3*1000 -> 3627.5 | I5: IEX Delivered | J5: Consumption | K5: Balance
A6: CTU | B6: ='Energy Schedule'!J3 -> 0.0343 | C6: =C5-(C5*$B$6) -> 0 | D6: =D5-(D5*$B$6) -> 8932.725 | E6: =E5-(E5*$B$6) -> 3503.0768 | H6: C1 | I6: =D33 -> 462.35606 | J6: ='Consumption Details'!$B5 -> 1800 | K6: =J6-I6 -> 1337.6439
A7: STU | B7: ='TNEB Charges'!B1 -> 0.0234 | C7: =C6-(C6*$B$7) -> 0 | D7: =D6-(D6*$B$7) -> 8723.6992 | E7: =E6-(E6*$B$7) -> 3421.1048 | H7: C2 | I7: =D34 -> 7053.2417 | J7: ='Consumption Details'!$C5 -> 10650 | K7: =J7-I7 -> 3596.7583
A8: Discom Losses | B8: ='TNEB Charges'!B2 -> 0.0195 | C8: =C7-(C7*$B$8) -> 0 | D8: =D7-(D7*$B$8) -> 8553.5871 | E8: =E7-(E7*$B$8) -> 3354.3932 | H8: C4 | I8: =D35 -> 2080.6023 | J8: ='Consumption Details'!$D5 -> 20350 | K8: =J8-I8 -> 18269.398
A9: Delivered @ Bus | B9: ='TNEB Charges'!B3 -> 0 | C9: =C8 -> 0 | D9: =D8 -> 8553.5871 | E9: =E8 -> 3354.3932 | H9: C5 | I9: =D36 -> 2311.7803 | J9: ='Consumption Details'!$E5 -> 3800 | K9: =J9-I9 -> 1488.2197
A10: IEX Payout / Unit | B10: ='TNEB Charges'!B4 -> 0 | C10: =C4/C9 -> #DIV/0! | D10: =D4/D9 -> 4.4806833 | E10: =E4/E9 -> 4.2653795
A11: IEX Transaction Charges | B11: ='TNEB Charges'!B5 -> 0.02 | C11: =(C3*1000*$B$11)+(C3*1000*$B$11*18%) -> 0 | D11: =(D3*1000*$B$11)+(D3*1000*$B$11*18%) -> 218.3 | E11: =(E3*1000*$B$11)+(E3*1000*$B$11*18%) -> 85.609
A12: NLDC Application fee | B12: ='TNEB Charges'!B6 -> 0 | C12: ='Energy Schedule'!I$6 -> 0 | D12: ='Energy Schedule'!J$6 -> 8.99 | E12: ='Energy Schedule'!K$6 -> 13.19
A13: CTU Transmission Charges | B13: ='TNEB Charges'!B7 -> 457.6 | C13: =C3*$B$13 -> 0 | D13: =D3*$B$13 -> 4232.8 | E13: =E3*$B$13 -> 1659.944
A14: NLDC Sched & Oprn Charges | B14: ='TNEB Charges'!B8 -> 1 | C14: =C3*$B$14 -> 0 | D14: =D3*$B$14 -> 9.25 | E14: =E3*$B$14 -> 3.6275
A15: STU Transmission Charges | B15: ='TNEB Charges'!B9 -> 260 | C15: =C3*$B$15 -> 0 | D15: =D3*$B$15 -> 2405 | E15: =E3*$B$15 -> 943.15
A16: STU Scheduling | B16: ='TNEB Charges'!B10 -> 170 | C16: =IF(C3>0,$B$16,0) -> 0 | D16: =IF(D3>0,$B$16,0) -> 170 | E16: =IF(E3>0,$B$16,0) -> 170
A17: STU System Operating Charge | B17: ='TNEB Charges'!B11 -> 33.74 | C17: =C3*$B$17/24 -> 0 | D17: =D3*$B$17/24 -> 13.003958 | E17: =E3*$B$17/24 -> 5.0996604
A18: TPTCL Margin | B18: ='TNEB Charges'!B12 -> 0.02 | C18: =C3*$B$18*1000 -> 0 | D18: =D3*$B$18*1000 -> 185 | E18: =E3*$B$18*1000 -> 72.55
A19: CSS | B19: ='TNEB Charges'!B13 -> 1.99 | C19: =C9*$B$19 -> 0 | D19: =D9*$B$19 -> 17021.638 | E19: =E9*$B$19 -> 6675.2425
A20: ASC | B20: ='TNEB Charges'!B14 -> 0 | C20: =C9*$B$20 -> 0 | D20: =D9*$B$20 -> 0 | E20: =E9*$B$20 -> 0
A21: Wheeling Charges | B21: ='TNEB Charges'!B15 -> 1.04 | C21: =C8*$B$21 -> 0 | D21: =D8*$B$21 -> 8895.7306 | E21: =E8*$B$21 -> 3488.5689
A22: E-Tax | B22: ='TNEB Charges'!B16 -> 0 | C22: =C9*$B$22 -> 0 | D22: =D9*$B$22 -> 0 | E22: =E9*$B$22 -> 0
A23: Solar RPO Charges | B23: ='TNEB Charges'!B17 -> 0.12 | C23: 0 | D23: =D9*$B$23*10.5% -> 107.7752 | E23: =E9*$B$23*10.5% -> 42.265354
A24: Non-Solar RPO Charges | B24: ='TNEB Charges'!B18 -> 0.12 | C24: 0 | D24: =D9*$B$24*10.5% -> 107.7752 | E24: =E9*$B$24*10.5% -> 42.265354
A25: Total Statutory Charges | C25: =SUM(C11:C24) -> 0 | D25: =SUM(D11:D24) -> 33375.263 | E25: =SUM(E11:E24) -> 13201.512
C26: =C25/C9 -> #DIV/0! | D26: =D25/D9 -> 3.9019025 | E26: =E25/E9 -> 3.9355888
A27: Total Cost incurred in IEX Purchase | C27: =C4+C25 -> 0 | D27: =D4+D25 -> 71701.178 | E27: =E4+E25 -> 27509.272
A28: Cost per Unit incurred | C28: =C27/C9 -> #DIV/0! | D28: =D27/D9 -> 8.3825858 | E28: =E27/E9 -> 8.2009683
I29: Slot | J29: Morning peak | K29: Evening peak | L29: Normal hour | M29: Normal hour | N29: Night Hour | O29: RTC
A30: EQUIVALENT EB PRICE TO THE UNITS PURCHASED FROM IEX | J30: C1 | K30: C2 | L30: C4 | M30: C5 | N30: C24
A31: DAM | I31: TNEB Tariff | J31: =$L$31+($L$31*25%) -> 10.625 | K31: =$L$31+($L$31*25%) -> 10.625 | L31: 8.5 | M31: =$L$31-($L$31*5%) -> 8.075 | N31: 6.03 | O31: =AVERAGE(J31:M31) -> 9.45625
A32: Slot | B32: Price | C32: Purchase | D32: Delivered | E32: EB Cost | I32: E-Tax | J32: 0.05 | K32: 0.05 | L32: 0.05 | M32: 0.05 | N32: 0.05 | O32: 0.05
A33: C1 | B33: =J33 -> 11.15625 | C33: =J39+J46+J53 -> 500 | D33: =M39+M46+M53 -> 462.35606 | E33: =D33*B33 -> 5158.1598 | I33: Total price/Unit | J33: =J31+(J31*J32) -> 11.15625 | K33: =K31+(K31*K32) -> 11.15625 | L33: =L31+(L31*L32) -> 8.925 | M33: =M31+(M31*M32) -> 8.47875 | N33: =N31+(N31*N32) -> 6.3315 | O33: =AVERAGE(J33:M33) -> 9.9290625
A34: C2 | B34: =K33 -> 11.15625 | C34: =J41+J48+J55 -> 7627.5 | D34: =M41+M48+M55 -> 7053.2417 | E34: =D34*B34 -> 78687.728
A35: C4 | B35: =L33 -> 8.925 | C35: =J38+J40+J45+J47+J52+J54 -> 2250 | D35: =M38+M40+M45+M47+M52+M54 -> 2080.6023 | E35: =D35*B35 -> 18569.375
A36: C5 | B36: =M33 -> 8.47875 | C36: =J37+J42+J44+J49+J51+J56 -> 2500 | D36: =M37+M42+M44+M49+M51+M56 -> 2311.7803 | E36: =D36*B36 -> 19601.007 | I36: GDAM
A37: Total | C37: =SUM(C33:C36) -> 12877.5 | D37: =SUM(D33:D36) -> 11907.98 | E37: =SUM(E33:E36) -> 122016.27 | H37: C5 | I37: =SUM('Energy Schedule'!I7:I26)/4 -> 0 | J37: =I37*1000 -> 0 | K37: =J37-(J37*$B$6) -> 0 | L37: =K37-(K37*$B$7) -> 0 | M37: =L37-(L37*$B$8) -> 0
H38: C4 | I38: =SUM('Energy Schedule'!I27:I30)/4 -> 0 | J38: =I38*1000 -> 0 | K38: =J38-(J38*$B$6) -> 0 | L38: =K38-(K38*$B$7) -> 0 | M38: =L38-(L38*$B$8) -> 0
H39: C1 | I39: =SUM('Energy Schedule'!I31:I46)/4 -> 0 | J39: =I39*1000 -> 0 | K39: =J39-(J39*$B$6) -> 0 | L39: =K39-(K39*$B$7) -> 0 | M39: =L39-(L39*$B$8) -> 0
H40: C4 | I40: =SUM('Energy Schedule'!I47:I78)/4 -> 0 | J40: =I40*1000 -> 0 | K40: =J40-(J40*$B$6) -> 0 | L40: =K40-(K40*$B$7) -> 0 | M40: =L40-(L40*$B$8) -> 0
H41: C2 | I41: =SUM('Energy Schedule'!I79:I94)/4 -> 0 | J41: =I41*1000 -> 0 | K41: =J41-(J41*$B$6) -> 0 | L41: =K41-(K41*$B$7) -> 0 | M41: =L41-(L41*$B$8) -> 0
...

Sheet 04
C2: G-DAM | D2: DAM | E2: RTM
A3: Unit Purchased in MWh | C3: ='Energy Schedule'!L$103 -> 0 | D3: ='Energy Schedule'!M$103 -> 20.375 | E3: ='Energy Schedule'!N$103 -> 3
A4: IEX Payout | C4: ='Energy Schedule'!L$5 -> 0 | D4: ='Energy Schedule'!M$5 -> 83092.96 | E4: ='Energy Schedule'!N$5 -> 12749.83
A5: Total Units in kWh | C5: =C3*1000 -> 0 | D5: =D3*1000 -> 20375 | E5: =E3*1000 -> 3000 | I5: IEX Delivered | J5: Consumption | K5: Balance
A6: CTU | B6: ='Energy Schedule'!M3 -> 0.0343 | C6: =C5-(C5*$B$6) -> 0 | D6: =D5-(D5*$B$6) -> 19676.138 | E6: =E5-(E5*$B$6) -> 2897.1 | H6: C1 | I6: =D33 -> 346.76704 | J6: ='Consumption Details'!$B6 -> 2050 | K6: =J6-I6 -> 1703.233
A7: STU | B7: ='TNEB Charges'!B1 -> 0.0234 | C7: =C6-(C6*$B$7) -> 0 | D7: =D6-(D6*$B$7) -> 19215.716 | E7: =E6-(E6*$B$7) -> 2829.3079 | H7: C2 | I7: =D34 -> 11096.545 | J7: ='Consumption Details'!$C6 -> 10600 | K7: =J7-I7 -> -496.54543
A8: Discom Losses | B8: ='TNEB Charges'!B2 -> 0.0195 | C8: =C7-(C7*$B$8) -> 0 | D8: =D7-(D7*$B$8) -> 18841.009 | E8: =E7-(E7*$B$8) -> 2774.1364 | H8: C4 | I8: =D35 -> 7397.697 | J8: ='Consumption Details'!$D6 -> 21850 | K8: =J8-I8 -> 14452.303
A9: Delivered @ Bus | B9: ='TNEB Charges'!B3 -> 0 | C9: =C8 -> 0 | D9: =D8 -> 18841.009 | E9: =E8 -> 2774.1364 | H9: C5 | I9: =D36 -> 2774.1364 | J9: ='Consumption Details'!$E6 -> 3750 | K9: =J9-I9 -> 975.86364
A10: IEX Payout / Unit | B10: ='TNEB Charges'!B4 -> 0 | C10: =C4/C9 -> #DIV/0! | D10: =D4/D9 -> 4.410218 | E10: =E4/E9 -> 4.5959637
A11: IEX Transaction Charges | B11: ='TNEB Charges'!B5 -> 0.02 | C11: =(C3*1000*$B$11)+(C3*1000*$B$11*18%) -> 0 | D11: =(D3*1000*$B$11)+(D3*1000*$B$11*18%) -> 480.85 | E11: =(E3*1000*$B$11)+(E3*1000*$B$11*18%) -> 70.8
A12: NLDC Application fee | B12: ='TNEB Charges'!B6 -> 0 | C12: ='Energy Schedule'!L$6 -> 0 | D12: ='Energy Schedule'!M$6 -> 7.67 | E12: ='Energy Schedule'!N$6 -> 14.29
A13: CTU Transmission Charges | B13: ='TNEB Charges'!B7 -> 457.6 | C13: =C3*$B$13 -> 0 | D13: =D3*$B$13 -> 9323.6 | E13: =E3*$B$13 -> 1372.8
A14: NLDC Sched & Oprn Charges | B14: ='TNEB Charges'!B8 -> 1 | C14: =C3*$B$14 -> 0 | D14: =D3*$B$14 -> 20.375 | E14: =E3*$B$14 -> 3
A15: STU Transmission Charges | B15: ='TNEB Charges'!B9 -> 260 | C15: =C3*$B$15 -> 0 | D15: =D3*$B$15 -> 5297.5 | E15: =E3*$B$15 -> 780
A16: STU Scheduling | B16: ='TNEB Charges'!B10 -> 170 | C16: =IF(C3>0,$B$16,0) -> 0 | D16: =IF(D3>0,$B$16,0) -> 170 | E16: =IF(E3>0,$B$16,0) -> 170
A17: STU System Operating Charge | B17: ='TNEB Charges'!B11 -> 33.74 | C17: =C3*$B$17/24 -> 0 | D17: =D3*$B$17/24 -> 28.643854 | E17: =E3*$B$17/24 -> 4.2175
A18: TPTCL Margin | B18: ='TNEB Charges'!B12 -> 0.02 | C18: =C3*$B$18*1000 -> 0 | D18: =D3*$B$18*1000 -> 407.5 | E18: =E3*$B$18*1000 -> 60
A19: CSS | B19: ='TNEB Charges'!B13 -> 1.99 | C19: =C9*$B$19 -> 0 | D19: =D9*$B$19 -> 37493.609 | E19: =E9*$B$19 -> 5520.5313
A20: ASC | B20: ='TNEB Charges'!B14 -> 0 | C20: =C9*$B$20 -> 0 | D20: =D9*$B$20 -> 0 | E20: =E9*$B$20 -> 0
A21: Wheeling Charges | B21: ='TNEB Charges'!B15 -> 1.04 | C21: =C8*$B$21 -> 0 | D21: =D8*$B$21 -> 19594.65 | E21: =E8*$B$21 -> 2885.1018
A22: E-Tax | B22: ='TNEB Charges'!B16 -> 0 | C22: =C9*$B$22 -> 0 | D22: =D9*$B$22 -> 0 | E22: =E9*$B$22 -> 0
A23: Solar RPO Charges | B23: ='TNEB Charges'!B17 -> 0.12 | C23: 0 | D23: =D9*$B$23*10.5% -> 237.39672 | E23: =E9*$B$23*10.5% -> 34.954118
A24: Non-Solar RPO Charges | B24: ='TNEB Charges'!B18 -> 0.12 | C24: 0 | D24: =D9*$B$24*10.5% -> 237.39672 | E24: =E9*$B$24*10.5% -> 34.954118
A25: Total Statutory Charges | C25: =SUM(C11:C24) -> 0 | D25: =SUM(D11:D24) -> 73299.191 | E25: =SUM(E11:E24) -> 10950.649
C26: =C25/C9 -> #DIV/0! | D26: =D25/D9 -> 3.8904068 | E26: =E25/E9 -> 3.9474083
A27: Total Cost incurred in IEX Purchase | C27: =C4+C25 -> 0 | D27: =D4+D25 -> 156392.15 | E27: =E4+E25 -> 23700.479
A28: Cost per Unit incurred | C28: =C27/C9 -> #DIV/0! | D28: =D27/D9 -> 8.3006248 | E28: =E27/E9 -> 8.543372
I29: Slot | J29: Morning peak | K29: Evening peak | L29: Normal hour | M29: Normal hour | N29: Night Hour | O29: RTC
A30: EQUIVALENT EB PRICE TO THE UNITS PURCHASED FROM IEX | J30: C1 | K30: C2 | L30: C4 | M30: C5 | N30: C24
A31: DAM | I31: TNEB Tariff | J31: =$L$31+($L$31*25%) -> 10.625 | K31: =$L$31+($L$31*25%) -> 10.625 | L31: 8.5 | M31: =$L$31-($L$31*5%) -> 8.075 | N31: 6.03 | O31: =AVERAGE(J31:M31) -> 9.45625
A32: Slot | B32: Price | C32: Purchase | D32: Delivered | E32: EB Cost | I32: E-Tax | J32: 0.05 | K32: 0.05 | L32: 0.05 | M32: 0.05 | N32: 0.05 | O32: 0.05
A33: C1 | B33: =J33 -> 11.15625 | C33: =J39+J46+J53 -> 375 | D33: =M39+M46+M53 -> 346.76704 | E33: =D33*B33 -> 3868.6198 | I33: Total price/Unit | J33: =J31+(J31*J32) -> 11.15625 | K33: =K31+(K31*K32) -> 11.15625 | L33: =L31+(L31*L32) -> 8.925 | M33: =M31+(M31*M32) -> 8.47875 | N33: =N31+(N31*N32) -> 6.3315 | O33: =AVERAGE(J33:M33) -> 9.9290625
A34: C2 | B34: =K33 -> 11.15625 | C34: =J41+J48+J55 -> 12000 | D34: =M41+M48+M55 -> 11096.545 | E34: =D34*B34 -> 123795.83
A35: C4 | B35: =L33 -> 8.925 | C35: =J38+J40+J45+J47+J52+J54 -> 8000 | D35: =M38+M40+M45+M47+M52+M54 -> 7397.697 | E35: =D35*B35 -> 66024.445
A36: C5 | B36: =M33 -> 8.47875 | C36: =J37+J42+J44+J49+J51+J56 -> 3000 | D36: =M37+M42+M44+M49+M51+M56 -> 2774.1364 | E36: =D36*B36 -> 23521.209 | I36: GDAM
A37: Total | C37: =SUM(C33:C36) -> 23375 | D37: =SUM(D33:D36) -> 21615.146 | E37: =SUM(E33:E36) -> 217210.11 | H37: C5 | I37: =SUM('Energy Schedule'!L7:L26)/4 -> 0 | J37: =I37*1000 -> 0 | K37: =J37-(J37*$B$6) -> 0 | L37: =K37-(K37*$B$7) -> 0 | M37: =L37-(L37*$B$8) -> 0
H38: C4 | I38: =SUM('Energy Schedule'!L27:L30)/4 -> 0 | J38: =I38*1000 -> 0 | K38: =J38-(J38*$B$6) -> 0 | L38: =K38-(K38*$B$7) -> 0 | M38: =L38-(L38*$B$8) -> 0
H39: C1 | I39: =SUM('Energy Schedule'!L31:L46)/4 -> 0 | J39: =I39*1000 -> 0 | K39: =J39-(J39*$B$6) -> 0 | L39: =K39-(K39*$B$7) -> 0 | M39: =L39-(L39*$B$8) -> 0
H40: C4 | I40: =SUM('Energy Schedule'!L47:L78)/4 -> 0 | J40: =I40*1000 -> 0 | K40: =J40-(J40*$B$6) -> 0 | L40: =K40-(K40*$B$7) -> 0 | M40: =L40-(L40*$B$8) -> 0
H41: C2 | I41: =SUM('Energy Schedule'!L79:L94)/4 -> 0 | J41: =I41*1000 -> 0 | K41: =J41-(J41*$B$6) -> 0 | L41: =K41-(K41*$B$7) -> 0 | M41: =L41-(L41*$B$8) -> 0
...

Sheet 05
C2: G-DAM | D2: DAM | E2: RTM
A3: Unit Purchased in MWh | C3: ='Energy Schedule'!O$103 -> 0 | D3: ='Energy Schedule'!P$103 -> 10 | E3: ='Energy Schedule'!Q$103 -> 3.75
A4: IEX Payout | C4: ='Energy Schedule'!O$5 -> 0 | D4: ='Energy Schedule'!P$5 -> 39837.968 | E4: ='Energy Schedule'!Q$5 -> 16147.49
A5: Total Units in kWh | C5: =C3*1000 -> 0 | D5: =D3*1000 -> 10000 | E5: =E3*1000 -> 3750 | I5: IEX Delivered | J5: Consumption | K5: Balance
A6: CTU | B6: ='Energy Schedule'!P3 -> 0.0361 | C6: =C5-(C5*$B$6) -> 0 | D6: =D5-(D5*$B$6) -> 9639 | E6: =E5-(E5*$B$6) -> 3614.625 | H6: C1 | I6: =D33 -> 346.12069 | J6: ='Consumption Details'!$B7 -> 1950 | K6: =J6-I6 -> 1603.8793
A7: STU | B7: ='TNEB Charges'!B1 -> 0.0234 | C7: =C6-(C6*$B$7) -> 0 | D7: =D6-(D6*$B$7) -> 9413.4474 | E7: =E6-(E6*$B$7) -> 3530.0428 | H7: C2 | I7: =D34 -> 7614.6553 | J7: ='Consumption Details'!$C7 -> 9300 | K7: =J7-I7 -> 1685.3447
A8: Discom Losses | B8: ='TNEB Charges'!B2 -> 0.0195 | C8: =C7-(C7*$B$8) -> 0 | D8: =D7-(D7*$B$8) -> 9229.8852 | E8: =E7-(E7*$B$8) -> 3461.2069 | H8: C4 | I8: =D35 -> 2307.4713 | J8: ='Consumption Details'!$D7 -> 19400 | K8: =J8-I8 -> 17092.529
A9: Delivered @ Bus | B9: ='TNEB Charges'!B3 -> 0 | C9: =C8 -> 0 | D9: =D8 -> 9229.8852 | E9: =E8 -> 3461.2069 | H9: C5 | I9: =D36 -> 2422.8449 | J9: ='Consumption Details'!$E7 -> 3400 | K9: =J9-I9 -> 977.15514
A10: IEX Payout / Unit | B10: ='TNEB Charges'!B4 -> 0 | C10: =C4/C9 -> #DIV/0! | D10: =D4/D9 -> 4.3161933 | E10: =E4/E9 -> 4.6652773
A11: IEX Transaction Charges | B11: ='TNEB Charges'!B5 -> 0.02 | C11: =(C3*1000*$B$11)+(C3*1000*$B$11*18%) -> 0 | D11: =(D3*1000*$B$11)+(D3*1000*$B$11*18%) -> 236 | E11: =(E3*1000*$B$11)+(E3*1000*$B$11*18%) -> 88.5
A12: NLDC Application fee | B12: ='TNEB Charges'!B6 -> 0 | C12: ='Energy Schedule'!O$6 -> 0 | D12: ='Energy Schedule'!P$6 -> 8.18 | E12: ='Energy Schedule'!Q$6 -> 13.55
A13: CTU Transmission Charges | B13: ='TNEB Charges'!B7 -> 457.6 | C13: =C3*$B$13 -> 0 | D13: =D3*$B$13 -> 4576 | E13: =E3*$B$13 -> 1716
A14: NLDC Sched & Oprn Charges | B14: ='TNEB Charges'!B8 -> 1 | C14: =C3*$B$14 -> 0 | D14: =D3*$B$14 -> 10 | E14: =E3*$B$14 -> 3.75
A15: STU Transmission Charges | B15: ='TNEB Charges'!B9 -> 260 | C15: =C3*$B$15 -> 0 | D15: =D3*$B$15 -> 2600 | E15: =E3*$B$15 -> 975
A16: STU Scheduling | B16: ='TNEB Charges'!B10 -> 170 | C16: =IF(C3>0,$B$16,0) -> 0 | D16: =IF(D3>0,$B$16,0) -> 170 | E16: =IF(E3>0,$B$16,0) -> 170
A17: STU System Operating Charge | B17: ='TNEB Charges'!B11 -> 33.74 | C17: =C3*$B$17/24 -> 0 | D17: =D3*$B$17/24 -> 14.058333 | E17: =E3*$B$17/24 -> 5.271875
A18: TPTCL Margin | B18: ='TNEB Charges'!B12 -> 0.02 | C18: =C3*$B$18*1000 -> 0 | D18: =D3*$B$18*1000 -> 200 | E18: =E3*$B$18*1000 -> 75
